<?xml version="1.0" ?>
<sdf version="1.5">
	<model name="stewart">
		<joint name="piston1_prismatic_joint" type="prismatic">
			<parent>piston1_cylinder_link</parent>
			<child>piston1_shaft_linkL</child>
			<pose>0 0 0 0 0 0</pose>
			<axis>
				<xyz>0 0 1</xyz>
				<limit>
					<lower>0.0</lower>
					<upper>0.14</upper>
					<velocity>1</velocity>
					<effort>100000</effort>
				</limit>
			</axis>
		</joint>
		<joint name="piston2_prismatic_joint" type="prismatic">
			<parent>piston2_cylinder_link</parent>
			<child>piston2_shaft_linkL</child>
			<pose>0 0 0 0 0 0</pose>
			<axis>
				<xyz>0 0 1</xyz>
				<limit>
					<lower>0.0</lower>
					<upper>0.14</upper>
					<velocity>1</velocity>
					<effort>100000</effort>
				</limit>
			</axis>
		</joint>
		<joint name="piston3_prismatic_joint" type="prismatic">
			<parent>piston3_cylinder_link</parent>
			<child>piston3_shaft_linkL</child>
			<pose>0 0 0 0 0 0</pose>
			<axis>
				<xyz>0 0 1</xyz>
				<limit>
					<lower>0.0</lower>
					<upper>0.14</upper>
					<velocity>1</velocity>
					<effort>100000</effort>
				</limit>
			</axis>
		</joint>
		<joint name="piston4_prismatic_joint" type="prismatic">
			<parent>piston4_cylinder_link</parent>
			<child>piston4_shaft_linkL</child>
			<pose>0 0 0 0 0 0</pose>
			<axis>
				<xyz>0 0 1</xyz>
				<limit>
					<lower>0.0</lower>
					<upper>0.14</upper>
					<velocity>1</velocity>
					<effort>100000</effort>
				</limit>
			</axis>
		</joint>
		<joint name="piston5_prismatic_joint" type="prismatic">
			<parent>piston5_cylinder_link</parent>
			<child>piston5_shaft_linkL</child>
			<pose>0 0 0 0 0 0</pose>
			<axis>
				<xyz>0 0 1</xyz>
				<limit>
					<lower>0.0</lower>
					<upper>0.14</upper>
					<velocity>1</velocity>
					<effort>100000</effort>
				</limit>
			</axis>
		</joint>
		<joint name="piston6_prismatic_joint" type="prismatic">
			<parent>piston6_cylinder_link</parent>
			<child>piston6_shaft_linkL</child>
			<pose>0 0 0 0 0 0</pose>
			<axis>
				<xyz>0 0 1</xyz>
				<limit>
					<lower>0.0</lower>
					<upper>0.14</upper>
					<velocity>1</velocity>
					<effort>100000</effort>
				</limit>
			</axis>
		</joint>
		<joint name="bottom_ball1_joint" type="revolute">
			<parent>base_link</parent>
			<child>bottom_ball1_link</child>
			<pose>0 0 0 0 0 0</pose>
			<axis>
				<xyz>0 1 0</xyz>
				<limit>
					<lower>-0.5235987755982988</lower>
					<upper>0.5235987755982988</upper>
					<velocity>1</velocity>
					<effort/>
				</limit>
			</axis>
		</joint>
		<joint name="bottom_ball2_joint" type="revolute">
			<parent>base_link</parent>
			<child>bottom_ball2_link</child>
			<pose>0 0 0 0 0 0</pose>
			<axis>
				<xyz>0 1 0</xyz>
				<limit>
					<lower>-0.5235987755982988</lower>
					<upper>0.5235987755982988</upper>
					<velocity>1</velocity>
					<effort/>
				</limit>
			</axis>
		</joint>
		<joint name="bottom_ball3_joint" type="revolute">
			<parent>base_link</parent>
			<child>bottom_ball3_link</child>
			<pose>0 0 0 0 0 0</pose>
			<axis>
				<xyz>0 1 0</xyz>
				<limit>
					<lower>-0.5235987755982988</lower>
					<upper>0.5235987755982988</upper>
					<velocity>1</velocity>
					<effort/>
				</limit>
			</axis>
		</joint>
		<joint name="bottom_ball4_joint" type="revolute">
			<parent>base_link</parent>
			<child>bottom_ball4_link</child>
			<pose>0 0 0 0 0 0</pose>
			<axis>
				<xyz>0 1 0</xyz>
				<limit>
					<lower>-0.5235987755982988</lower>
					<upper>0.5235987755982988</upper>
					<velocity>1</velocity>
					<effort/>
				</limit>
			</axis>
		</joint>
		<joint name="bottom_ball5_joint" type="revolute">
			<parent>base_link</parent>
			<child>bottom_ball5_link</child>
			<pose>0 0 0 0 0 0</pose>
			<axis>
				<xyz>0 1 0</xyz>
				<limit>
					<lower>-0.5235987755982988</lower>
					<upper>0.5235987755982988</upper>
					<velocity>1</velocity>
					<effort/>
				</limit>
			</axis>
		</joint>
		<joint name="bottom_ball6_joint" type="revolute">
			<parent>base_link</parent>
			<child>bottom_ball6_link</child>
			<pose>0 0 0 0 0 0</pose>
			<axis>
				<xyz>0 1 0</xyz>
				<limit>
					<lower>-0.5235987755982988</lower>
					<upper>0.5235987755982988</upper>
					<velocity>1</velocity>
					<effort/>
				</limit>
			</axis>
		</joint>
		<joint name="piston1_bottom_pitch_joint" type="ball">
			<parent>bottom_ball1_link</parent>
			<child>piston1_cylinder_link</child>
			<pose>0 0 -0.11403052302243251 0 0 0</pose>
		</joint>
		<joint name="piston2_bottom_pitch_joint" type="ball">
			<parent>bottom_ball2_link</parent>
			<child>piston2_cylinder_link</child>
			<pose>0 0 -0.11403052302243251 0 0 0</pose>
		</joint>
		<joint name="piston3_bottom_pitch_joint" type="ball">
			<parent>bottom_ball3_link</parent>
			<child>piston3_cylinder_link</child>
			<pose>0 0 -0.11403052302243251 0 0 0</pose>
		</joint>
		<joint name="piston4_bottom_pitch_joint" type="ball">
			<parent>bottom_ball4_link</parent>
			<child>piston4_cylinder_link</child>
			<pose>0 0 -0.11403052302243251 0 0 0</pose>
		</joint>
		<joint name="piston5_bottom_pitch_joint" type="ball">
			<parent>bottom_ball5_link</parent>
			<child>piston5_cylinder_link</child>
			<pose>0 0 -0.11403052302243251 0 0 0</pose>
		</joint>
		<joint name="piston6_bottom_pitch_joint" type="ball">
			<parent>bottom_ball6_link</parent>
			<child>piston6_cylinder_link</child>
			<pose>0 0 -0.11403052302243251 0 0 0</pose>
		</joint>
		<joint name="top_ball1_joint" type="revolute">
			<parent>platform_link</parent>
			<child>top_ball1_link</child>
			<pose>0 0 0 0 0 0</pose>
			<axis>
				<xyz>0 1 0</xyz>
				<limit>
					<lower>-0.5235987755982988</lower>
					<upper>0.5235987755982988</upper>
					<velocity>1</velocity>
					<effort/>
				</limit>
			</axis>
			<axis2>
				<xyz>0 0 1</xyz>
				<limit>
					<lower>-0.5235987755982988</lower>
					<upper>0.5235987755982988</upper>
					<velocity>1</velocity>
					<effort/>
				</limit>
			</axis2>
		</joint>
		<joint name="top_ball2_joint" type="revolute">
			<parent>platform_link</parent>
			<child>top_ball2_link</child>
			<pose>0 0 0 0 0 0</pose>
			<axis>
				<xyz>0 1 0</xyz>
				<limit>
					<lower>-0.5235987755982988</lower>
					<upper>0.5235987755982988</upper>
					<velocity>1</velocity>
					<effort/>
				</limit>
			</axis>
			<axis2>
				<xyz>0 0 1</xyz>
				<limit>
					<lower>-0.5235987755982988</lower>
					<upper>0.5235987755982988</upper>
					<velocity>1</velocity>
					<effort/>
				</limit>
			</axis2>
		</joint>
		<joint name="top_ball3_joint" type="revolute">
			<parent>platform_link</parent>
			<child>top_ball3_link</child>
			<pose>0 0 0 0 0 0</pose>
			<axis>
				<xyz>0 1 0</xyz>
				<limit>
					<lower>-0.5235987755982988</lower>
					<upper>0.5235987755982988</upper>
					<velocity>1</velocity>
					<effort/>
				</limit>
			</axis>
			<axis2>
				<xyz>0 0 1</xyz>
				<limit>
					<lower>-0.5235987755982988</lower>
					<upper>0.5235987755982988</upper>
					<velocity>1</velocity>
					<effort/>
				</limit>
			</axis2>
		</joint>
		<joint name="top_ball4_joint" type="revolute">
			<parent>platform_link</parent>
			<child>top_ball4_link</child>
			<pose>0 0 0 0 0 0</pose>
			<axis>
				<xyz>0 1 0</xyz>
				<limit>
					<lower>-0.5235987755982988</lower>
					<upper>0.5235987755982988</upper>
					<velocity>1</velocity>
					<effort/>
				</limit>
			</axis>
			<axis2>
				<xyz>0 0 1</xyz>
				<limit>
					<lower>-0.5235987755982988</lower>
					<upper>0.5235987755982988</upper>
					<velocity>1</velocity>
					<effort/>
				</limit>
			</axis2>
		</joint>
		<joint name="top_ball5_joint" type="revolute">
			<parent>platform_link</parent>
			<child>top_ball5_link</child>
			<pose>0 0 0 0 0 0</pose>
			<axis>
				<xyz>0 1 0</xyz>
				<limit>
					<lower>-0.5235987755982988</lower>
					<upper>0.5235987755982988</upper>
					<velocity>1</velocity>
					<effort/>
				</limit>
			</axis>
			<axis2>
				<xyz>0 0 1</xyz>
				<limit>
					<lower>-0.5235987755982988</lower>
					<upper>0.5235987755982988</upper>
					<velocity>1</velocity>
					<effort/>
				</limit>
			</axis2>
		</joint>
		<joint name="top_ball6_joint" type="revolute">
			<parent>platform_link</parent>
			<child>top_ball6_link</child>
			<pose>0 0 0 0 0 0</pose>
			<axis>
				<xyz>0 1 0</xyz>
				<limit>
					<lower>-0.5235987755982988</lower>
					<upper>0.5235987755982988</upper>
					<velocity>1</velocity>
					<effort/>
				</limit>
			</axis>
			<axis2>
				<xyz>0 0 1</xyz>
				<limit>
					<lower>-0.5235987755982988</lower>
					<upper>0.5235987755982988</upper>
					<velocity>1</velocity>
					<effort/>
				</limit>
			</axis2>
		</joint>
		<joint name="piston1_top_pitch_joint" type="universal">
			<parent>top_ball1_link</parent>
			<child>piston1_shaft_linkU</child>
			<pose>0 0 0.11403052302243251 0 0 0</pose>
			<axis>
				<xyz>1 0 0</xyz>
				<limit>
					<lower>-0.5235987755982988</lower>
					<upper>0.5235987755982988</upper>
					<velocity/>
					<effort/>
				</limit>
			</axis>
		</joint>
		<joint name="piston2_top_pitch_joint" type="universal">
			<parent>top_ball2_link</parent>
			<child>piston2_shaft_linkU</child>
			<pose>0 0 0.11403052302243251 0 0 0</pose>
			<axis>
				<xyz>1 0 0</xyz>
				<limit>
					<lower>-0.5235987755982988</lower>
					<upper>0.5235987755982988</upper>
					<velocity/>
					<effort/>
				</limit>
			</axis>
		</joint>
		<joint name="piston3_top_pitch_joint" type="universal">
			<parent>top_ball3_link</parent>
			<child>piston3_shaft_linkU</child>
			<pose>0 0 0.11403052302243251 0 0 0</pose>
			<axis>
				<xyz>1 0 0</xyz>
				<limit>
					<lower>-0.5235987755982988</lower>
					<upper>0.5235987755982988</upper>
					<velocity/>
					<effort/>
				</limit>
			</axis>
		</joint>
		<joint name="piston4_top_pitch_joint" type="universal">
			<parent>top_ball4_link</parent>
			<child>piston4_shaft_linkU</child>
			<pose>0 0 0.11403052302243251 0 0 0</pose>
			<axis>
				<xyz>1 0 0</xyz>
				<limit>
					<lower>-0.5235987755982988</lower>
					<upper>0.5235987755982988</upper>
					<velocity/>
					<effort/>
				</limit>
			</axis>
		</joint>
		<joint name="piston5_top_pitch_joint" type="universal">
			<parent>top_ball5_link</parent>
			<child>piston5_shaft_linkU</child>
			<pose>0 0 0.11403052302243251 0 0 0</pose>
			<axis>
				<xyz>1 0 0</xyz>
				<limit>
					<lower>-0.5235987755982988</lower>
					<upper>0.5235987755982988</upper>
					<velocity/>
					<effort/>
				</limit>
			</axis>
		</joint>
		<joint name="piston6_top_pitch_joint" type="universal">
			<parent>top_ball6_link</parent>
			<child>piston6_shaft_linkU</child>
			<pose>0 0 0.11403052302243251 0 0 0</pose>
			<axis>
				<xyz>1 0 0</xyz>
				<limit>
					<lower>-0.5235987755982988</lower>
					<upper>0.5235987755982988</upper>
					<velocity/>
					<effort/>
				</limit>
			</axis>
		</joint>
		<link name="base_link">
			<pose>0 0 0.0075 0 0 0</pose>
			<visual name="base_link_visual">
				<geometry>
					<cylinder>
						<radius>0.1</radius>
						<length>0.015</length>
					</cylinder>
				</geometry>
				<material>
					<script>
						<uri>file://media/materials/scripts/gazebo.material</uri>
						<name>Gazebo/Trunk</name>
					</script>
				</material>
			</visual>
			<collision name="base_link_collision">
				<geometry>
					<cylinder>
						<radius>0.1</radius>
						<length>0.015</length>
					</cylinder>
				</geometry>
			</collision>
		</link>
		<link name="platform_link">
			<pose>0 0 0.2575 0 0 0</pose>
			<visual name="platform_link_visual">
				<geometry>
					<cylinder>
						<radius>0.1</radius>
						<length>0.015</length>
					</cylinder>
				</geometry>
				<material>
					<script>
						<uri>file://media/materials/scripts/gazebo.material</uri>
						<name>Gazebo/Footway</name>
					</script>
				</material>
			</visual>
			<collision name="platform_link_collision">
				<geometry>
					<cylinder>
						<radius>0.1</radius>
						<length>0.015</length>
					</cylinder>
				</geometry>
			</collision>
		</link>
		<link name="bottom_ball1_link">
			<pose>0.08965752282825709 0.007844016847289225 0.015 0 0 0.08726646259971638</pose>
			<visual name="bottom_ball1_link_visual">
				<geometry>
					<sphere>
						<radius>0.01</radius>
					</sphere>
				</geometry>
				<material>
					<script>
						<uri>file://media/materials/scripts/gazebo.material</uri>
						<name>Gazebo/Gold</name>
					</script>
				</material>
			</visual>
		</link>
		<link name="bottom_ball2_link">
			<pose>-0.03803564355666294 0.0815677008332985 0.015 0 0 2.007128639793479</pose>
			<visual name="bottom_ball2_link_visual">
				<geometry>
					<sphere>
						<radius>0.01</radius>
					</sphere>
				</geometry>
				<material>
					<script>
						<uri>file://media/materials/scripts/gazebo.material</uri>
						<name>Gazebo/Gold</name>
					</script>
				</material>
			</visual>
		</link>
		<link name="bottom_ball3_link">
			<pose>-0.05162187927159415 0.07372368398600924 0.015 0 0 2.181661564992912</pose>
			<visual name="bottom_ball3_link_visual">
				<geometry>
					<sphere>
						<radius>0.01</radius>
					</sphere>
				</geometry>
				<material>
					<script>
						<uri>file://media/materials/scripts/gazebo.material</uri>
						<name>Gazebo/Gold</name>
					</script>
				</material>
			</visual>
		</link>
		<link name="bottom_ball4_link">
			<pose>-0.05162187927159411 -0.07372368398600929 0.015 0 0 -2.1816615649929116</pose>
			<visual name="bottom_ball4_link_visual">
				<geometry>
					<sphere>
						<radius>0.01</radius>
					</sphere>
				</geometry>
				<material>
					<script>
						<uri>file://media/materials/scripts/gazebo.material</uri>
						<name>Gazebo/Gold</name>
					</script>
				</material>
			</visual>
		</link>
		<link name="bottom_ball5_link">
			<pose>-0.038035643556662925 -0.0815677008332985 0.015 0 0 -2.007128639793479</pose>
			<visual name="bottom_ball5_link_visual">
				<geometry>
					<sphere>
						<radius>0.01</radius>
					</sphere>
				</geometry>
				<material>
					<script>
						<uri>file://media/materials/scripts/gazebo.material</uri>
						<name>Gazebo/Gold</name>
					</script>
				</material>
			</visual>
		</link>
		<link name="bottom_ball6_link">
			<pose>0.08965752282825709 -0.007844016847289248 0.015 0 0 -0.08726646259971663</pose>
			<visual name="bottom_ball6_link_visual">
				<geometry>
					<sphere>
						<radius>0.01</radius>
					</sphere>
				</geometry>
				<material>
					<script>
						<uri>file://media/materials/scripts/gazebo.material</uri>
						<name>Gazebo/Gold</name>
					</script>
				</material>
			</visual>
		</link>
		<link name="top_ball1_link">
			<pose>0.05162187927159415 0.07372368398600924 0.2425 0 0 0.9599310885968811</pose>
			<visual name="top_ball1_link_visual">
				<geometry>
					<sphere>
						<radius>0.01</radius>
					</sphere>
				</geometry>
				<material>
					<script>
						<uri>file://media/materials/scripts/gazebo.material</uri>
						<name>Gazebo/White</name>
					</script>
				</material>
			</visual>
		</link>
		<link name="top_ball2_link">
			<pose>0.03803564355666297 0.08156770083329848 0.2425 0 0 1.134464013796314</pose>
			<visual name="top_ball2_link_visual">
				<geometry>
					<sphere>
						<radius>0.01</radius>
					</sphere>
				</geometry>
				<material>
					<script>
						<uri>file://media/materials/scripts/gazebo.material</uri>
						<name>Gazebo/White</name>
					</script>
				</material>
			</visual>
		</link>
		<link name="top_ball3_link">
			<pose>-0.08965752282825709 0.007844016847289238 0.2425 0 0 3.0543261909900767</pose>
			<visual name="top_ball3_link_visual">
				<geometry>
					<sphere>
						<radius>0.01</radius>
					</sphere>
				</geometry>
				<material>
					<script>
						<uri>file://media/materials/scripts/gazebo.material</uri>
						<name>Gazebo/White</name>
					</script>
				</material>
			</visual>
		</link>
		<link name="top_ball4_link">
			<pose>-0.08965752282825709 -0.007844016847289215 0.2425 0 0 -3.054326190990077</pose>
			<visual name="top_ball4_link_visual">
				<geometry>
					<sphere>
						<radius>0.01</radius>
					</sphere>
				</geometry>
				<material>
					<script>
						<uri>file://media/materials/scripts/gazebo.material</uri>
						<name>Gazebo/White</name>
					</script>
				</material>
			</visual>
		</link>
		<link name="top_ball5_link">
			<pose>0.03803564355666297 -0.08156770083329849 0.2425 0 0 -1.134464013796314</pose>
			<visual name="top_ball5_link_visual">
				<geometry>
					<sphere>
						<radius>0.01</radius>
					</sphere>
				</geometry>
				<material>
					<script>
						<uri>file://media/materials/scripts/gazebo.material</uri>
						<name>Gazebo/White</name>
					</script>
				</material>
			</visual>
		</link>
		<link name="top_ball6_link">
			<pose>0.051621879271594145 -0.07372368398600926 0.2425 0 0 -0.9599310885968813</pose>
			<visual name="top_ball6_link_visual">
				<geometry>
					<sphere>
						<radius>0.01</radius>
					</sphere>
				</geometry>
				<material>
					<script>
						<uri>file://media/materials/scripts/gazebo.material</uri>
						<name>Gazebo/White</name>
					</script>
				</material>
			</visual>
		</link>
		<link name="piston1_cylinder_link">
			<pose>0.07063970104992562 0.04078385041664923 0.13249999999999998 0 0.34007382246493445 2.0943951023931953</pose>
			<visual name="piston1_cylinder_link_visual">
				<geometry>
					<cylinder>
						<radius>0.005</radius>
						<length>0.22806104604486502</length>
					</cylinder>
				</geometry>
				<material>
					<script>
						<uri>file://media/materials/scripts/gazebo.material</uri>
						<name>Gazebo/DarkGrey</name>
					</script>
				</material>
			</visual>
		</link>
		<link name="piston2_cylinder_link">
			<pose>1.3877787807814457e-17 0.08156770083329849 0.13249999999999998 0 0.34007382246493445 -3.6486270535005563e-16</pose>
			<visual name="piston2_cylinder_link_visual">
				<geometry>
					<cylinder>
						<radius>0.005</radius>
						<length>0.22806104604486502</length>
					</cylinder>
				</geometry>
				<material>
					<script>
						<uri>file://media/materials/scripts/gazebo.material</uri>
						<name>Gazebo/DarkGrey</name>
					</script>
				</material>
			</visual>
		</link>
		<link name="piston3_cylinder_link">
			<pose>-0.07063970104992562 0.04078385041664924 0.13249999999999998 0 0.34007382246493423 -2.0943951023931953</pose>
			<visual name="piston3_cylinder_link_visual">
				<geometry>
					<cylinder>
						<radius>0.005</radius>
						<length>0.22806104604486502</length>
					</cylinder>
				</geometry>
				<material>
					<script>
						<uri>file://media/materials/scripts/gazebo.material</uri>
						<name>Gazebo/DarkGrey</name>
					</script>
				</material>
			</visual>
		</link>
		<link name="piston4_cylinder_link">
			<pose>-0.0706397010499256 -0.04078385041664925 0.13249999999999998 0 0.34007382246493467 2.0943951023931957</pose>
			<visual name="piston4_cylinder_link_visual">
				<geometry>
					<cylinder>
						<radius>0.005</radius>
						<length>0.22806104604486502</length>
					</cylinder>
				</geometry>
				<material>
					<script>
						<uri>file://media/materials/scripts/gazebo.material</uri>
						<name>Gazebo/DarkGrey</name>
					</script>
				</material>
			</visual>
		</link>
		<link name="piston5_cylinder_link">
			<pose>2.0816681711721685e-17 -0.0815677008332985 0.13249999999999998 0 0.34007382246493445 1.8243135267502784e-16</pose>
			<visual name="piston5_cylinder_link_visual">
				<geometry>
					<cylinder>
						<radius>0.005</radius>
						<length>0.22806104604486502</length>
					</cylinder>
				</geometry>
				<material>
					<script>
						<uri>file://media/materials/scripts/gazebo.material</uri>
						<name>Gazebo/DarkGrey</name>
					</script>
				</material>
			</visual>
		</link>
		<link name="piston6_cylinder_link">
			<pose>0.07063970104992562 -0.04078385041664925 0.13249999999999998 0 0.34007382246493423 -2.0943951023931957</pose>
			<visual name="piston6_cylinder_link_visual">
				<geometry>
					<cylinder>
						<radius>0.005</radius>
						<length>0.22806104604486502</length>
					</cylinder>
				</geometry>
				<material>
					<script>
						<uri>file://media/materials/scripts/gazebo.material</uri>
						<name>Gazebo/DarkGrey</name>
					</script>
				</material>
			</visual>
		</link>
		<link name="piston1_shaft_linkU">
			<pose>0.07063970104992562 0.04078385041664923 0.13249999999999998 0 0.34007382246493445 2.0943951023931953</pose>
			<visual name="piston1_shaft_linkU_visual">
				<geometry>
					<cylinder>
						<radius>0.0025</radius>
						<length>0.22806104604486502</length>
					</cylinder>
				</geometry>
				<material>
					<script>
						<uri>file://media/materials/scripts/gazebo.material</uri>
						<name>Gazebo/Black</name>
					</script>
				</material>
			</visual>
		</link>
		<link name="piston2_shaft_linkU">
			<pose>1.3877787807814457e-17 0.08156770083329849 0.13249999999999998 0 0.34007382246493445 -3.6486270535005563e-16</pose>
			<visual name="piston2_shaft_linkU_visual">
				<geometry>
					<cylinder>
						<radius>0.0025</radius>
						<length>0.22806104604486502</length>
					</cylinder>
				</geometry>
				<material>
					<script>
						<uri>file://media/materials/scripts/gazebo.material</uri>
						<name>Gazebo/Black</name>
					</script>
				</material>
			</visual>
		</link>
		<link name="piston3_shaft_linkU">
			<pose>-0.07063970104992562 0.04078385041664924 0.13249999999999998 0 0.34007382246493423 -2.0943951023931953</pose>
			<visual name="piston3_shaft_linkU_visual">
				<geometry>
					<cylinder>
						<radius>0.0025</radius>
						<length>0.22806104604486502</length>
					</cylinder>
				</geometry>
				<material>
					<script>
						<uri>file://media/materials/scripts/gazebo.material</uri>
						<name>Gazebo/Black</name>
					</script>
				</material>
			</visual>
		</link>
		<link name="piston4_shaft_linkU">
			<pose>-0.0706397010499256 -0.04078385041664925 0.13249999999999998 0 0.34007382246493467 2.0943951023931957</pose>
			<visual name="piston4_shaft_linkU_visual">
				<geometry>
					<cylinder>
						<radius>0.0025</radius>
						<length>0.22806104604486502</length>
					</cylinder>
				</geometry>
				<material>
					<script>
						<uri>file://media/materials/scripts/gazebo.material</uri>
						<name>Gazebo/Black</name>
					</script>
				</material>
			</visual>
		</link>
		<link name="piston5_shaft_linkU">
			<pose>2.0816681711721685e-17 -0.0815677008332985 0.13249999999999998 0 0.34007382246493445 1.8243135267502784e-16</pose>
			<visual name="piston5_shaft_linkU_visual">
				<geometry>
					<cylinder>
						<radius>0.0025</radius>
						<length>0.22806104604486502</length>
					</cylinder>
				</geometry>
				<material>
					<script>
						<uri>file://media/materials/scripts/gazebo.material</uri>
						<name>Gazebo/Black</name>
					</script>
				</material>
			</visual>
		</link>
		<link name="piston6_shaft_linkU">
			<pose>0.07063970104992562 -0.04078385041664925 0.13249999999999998 0 0.34007382246493423 -2.0943951023931957</pose>
			<visual name="piston6_shaft_linkU_visual">
				<geometry>
					<cylinder>
						<radius>0.0025</radius>
						<length>0.22806104604486502</length>
					</cylinder>
				</geometry>
				<material>
					<script>
						<uri>file://media/materials/scripts/gazebo.material</uri>
						<name>Gazebo/Black</name>
					</script>
				</material>
			</visual>
		</link>
		<link name="piston1_shaft_linkL">
			<pose>0.07063970104992562 0.04078385041664923 0.13249999999999998 0 0.34007382246493445 2.0943951023931953</pose>
			<visual name="piston1_shaft_linkL_visual">
				<geometry>
					<cylinder>
						<radius>0.0025</radius>
						<length>0.22806104604486502</length>
					</cylinder>
				</geometry>
				<material>
					<script>
						<uri>file://media/materials/scripts/gazebo.material</uri>
						<name>Gazebo/Black</name>
					</script>
				</material>
			</visual>
		</link>
		<link name="piston2_shaft_linkL">
			<pose>1.3877787807814457e-17 0.08156770083329849 0.13249999999999998 0 0.34007382246493445 -3.6486270535005563e-16</pose>
			<visual name="piston2_shaft_linkL_visual">
				<geometry>
					<cylinder>
						<radius>0.0025</radius>
						<length>0.22806104604486502</length>
					</cylinder>
				</geometry>
				<material>
					<script>
						<uri>file://media/materials/scripts/gazebo.material</uri>
						<name>Gazebo/Black</name>
					</script>
				</material>
			</visual>
		</link>
		<link name="piston3_shaft_linkL">
			<pose>-0.07063970104992562 0.04078385041664924 0.13249999999999998 0 0.34007382246493423 -2.0943951023931953</pose>
			<visual name="piston3_shaft_linkL_visual">
				<geometry>
					<cylinder>
						<radius>0.0025</radius>
						<length>0.22806104604486502</length>
					</cylinder>
				</geometry>
				<material>
					<script>
						<uri>file://media/materials/scripts/gazebo.material</uri>
						<name>Gazebo/Black</name>
					</script>
				</material>
			</visual>
		</link>
		<link name="piston4_shaft_linkL">
			<pose>-0.0706397010499256 -0.04078385041664925 0.13249999999999998 0 0.34007382246493467 2.0943951023931957</pose>
			<visual name="piston4_shaft_linkL_visual">
				<geometry>
					<cylinder>
						<radius>0.0025</radius>
						<length>0.22806104604486502</length>
					</cylinder>
				</geometry>
				<material>
					<script>
						<uri>file://media/materials/scripts/gazebo.material</uri>
						<name>Gazebo/Black</name>
					</script>
				</material>
			</visual>
		</link>
		<link name="piston5_shaft_linkL">
			<pose>2.0816681711721685e-17 -0.0815677008332985 0.13249999999999998 0 0.34007382246493445 1.8243135267502784e-16</pose>
			<visual name="piston5_shaft_linkL_visual">
				<geometry>
					<cylinder>
						<radius>0.0025</radius>
						<length>0.22806104604486502</length>
					</cylinder>
				</geometry>
				<material>
					<script>
						<uri>file://media/materials/scripts/gazebo.material</uri>
						<name>Gazebo/Black</name>
					</script>
				</material>
			</visual>
		</link>
		<link name="piston6_shaft_linkL">
			<pose>0.07063970104992562 -0.04078385041664925 0.13249999999999998 0 0.34007382246493423 -2.0943951023931957</pose>
			<visual name="piston6_shaft_linkL_visual">
				<geometry>
					<cylinder>
						<radius>0.0025</radius>
						<length>0.22806104604486502</length>
					</cylinder>
				</geometry>
				<material>
					<script>
						<uri>file://media/materials/scripts/gazebo.material</uri>
						<name>Gazebo/Black</name>
					</script>
				</material>
			</visual>
		</link>
		<plugin filename="libgz-sim-detachable-joint-system.so" name="gz::sim::systems::DetachableJoint">
			<parent_link>piston1_shaft_linkL</parent_link>
			<child_link>piston1_shaft_linkU</child_link>
			<child_model>stewart</child_model>
		</plugin>
		<plugin filename="libgz-sim-detachable-joint-system.so" name="gz::sim::systems::DetachableJoint">
			<parent_link>piston2_shaft_linkL</parent_link>
			<child_link>piston2_shaft_linkU</child_link>
			<child_model>stewart</child_model>
		</plugin>
		<plugin filename="libgz-sim-detachable-joint-system.so" name="gz::sim::systems::DetachableJoint">
			<parent_link>piston3_shaft_linkL</parent_link>
			<child_link>piston3_shaft_linkU</child_link>
			<child_model>stewart</child_model>
		</plugin>
		<plugin filename="libgz-sim-detachable-joint-system.so" name="gz::sim::systems::DetachableJoint">
			<parent_link>piston4_shaft_linkL</parent_link>
			<child_link>piston4_shaft_linkU</child_link>
			<child_model>stewart</child_model>
		</plugin>
		<plugin filename="libgz-sim-detachable-joint-system.so" name="gz::sim::systems::DetachableJoint">
			<parent_link>piston5_shaft_linkL</parent_link>
			<child_link>piston5_shaft_linkU</child_link>
			<child_model>stewart</child_model>
		</plugin>
		<plugin filename="libgz-sim-detachable-joint-system.so" name="gz::sim::systems::DetachableJoint">
			<parent_link>piston6_shaft_linkL</parent_link>
			<child_link>piston6_shaft_linkU</child_link>
			<child_model>stewart</child_model>
		</plugin>
		<plugin filename="gz-sim-joint-position-controller-system" name="gz::sim::systems::JointPositionController">
			<joint_name>piston1_prismatic_joint</joint_name>
			<p_gain>1000000</p_gain>
			<i_gain>10</i_gain>
			<d_gain>100000</d_gain>
		</plugin>
		<plugin filename="gz-sim-joint-position-controller-system" name="gz::sim::systems::JointPositionController">
			<joint_name>piston2_prismatic_joint</joint_name>
			<p_gain>1000000</p_gain>
			<i_gain>10</i_gain>
			<d_gain>100000</d_gain>
		</plugin>
		<plugin filename="gz-sim-joint-position-controller-system" name="gz::sim::systems::JointPositionController">
			<joint_name>piston3_prismatic_joint</joint_name>
			<p_gain>1000000</p_gain>
			<i_gain>10</i_gain>
			<d_gain>100000</d_gain>
		</plugin>
		<plugin filename="gz-sim-joint-position-controller-system" name="gz::sim::systems::JointPositionController">
			<joint_name>piston4_prismatic_joint</joint_name>
			<p_gain>1000000</p_gain>
			<i_gain>10</i_gain>
			<d_gain>100000</d_gain>
		</plugin>
		<plugin filename="gz-sim-joint-position-controller-system" name="gz::sim::systems::JointPositionController">
			<joint_name>piston5_prismatic_joint</joint_name>
			<p_gain>1000000</p_gain>
			<i_gain>10</i_gain>
			<d_gain>100000</d_gain>
		</plugin>
		<plugin filename="gz-sim-joint-position-controller-system" name="gz::sim::systems::JointPositionController">
			<joint_name>piston6_prismatic_joint</joint_name>
			<p_gain>1000000</p_gain>
			<i_gain>10</i_gain>
			<d_gain>100000</d_gain>
		</plugin>
	</model>
</sdf>
