<?xml version="1.0" ?>
<sdf version="1.5">
	<model name="stewart">
		<plugin name="gz::sim::systems::PosePublisher" filename="gz-sim-pose-publisher-system">
			<publish_link_pose>true</publish_link_pose>
			<use_pose_vector_msg>true</use_pose_vector_msg>
			<static_publisher>false</static_publisher>
			<static_update_frequency>1</static_update_frequency>
		</plugin>
		<plugin name="gz::sim::systems::JointStatePublisher" filename="gz-sim-joint-state-publisher-system"/>
		<joint name="piston1_prismatic_joint" type="prismatic">
			<parent>piston1_cylinder_link</parent>
			<child>piston1_shaft_linkL</child>
			<pose>0 0 0 0 0 0</pose>
			<axis>
				<xyz>0 0 1</xyz>
				<limit>
					<lower>0.0</lower>
					<upper>0.2</upper>
					<velocity>1</velocity>
					<effort>100000</effort>
				</limit>
			</axis>
		</joint>
		<joint name="piston2_prismatic_joint" type="prismatic">
			<parent>piston2_cylinder_link</parent>
			<child>piston2_shaft_linkL</child>
			<pose>0 0 0 0 0 0</pose>
			<axis>
				<xyz>0 0 1</xyz>
				<limit>
					<lower>0.0</lower>
					<upper>0.2</upper>
					<velocity>1</velocity>
					<effort>100000</effort>
				</limit>
			</axis>
		</joint>
		<joint name="piston3_prismatic_joint" type="prismatic">
			<parent>piston3_cylinder_link</parent>
			<child>piston3_shaft_linkL</child>
			<pose>0 0 0 0 0 0</pose>
			<axis>
				<xyz>0 0 1</xyz>
				<limit>
					<lower>0.0</lower>
					<upper>0.2</upper>
					<velocity>1</velocity>
					<effort>100000</effort>
				</limit>
			</axis>
		</joint>
		<joint name="piston4_prismatic_joint" type="prismatic">
			<parent>piston4_cylinder_link</parent>
			<child>piston4_shaft_linkL</child>
			<pose>0 0 0 0 0 0</pose>
			<axis>
				<xyz>0 0 1</xyz>
				<limit>
					<lower>0.0</lower>
					<upper>0.2</upper>
					<velocity>1</velocity>
					<effort>100000</effort>
				</limit>
			</axis>
		</joint>
		<joint name="piston5_prismatic_joint" type="prismatic">
			<parent>piston5_cylinder_link</parent>
			<child>piston5_shaft_linkL</child>
			<pose>0 0 0 0 0 0</pose>
			<axis>
				<xyz>0 0 1</xyz>
				<limit>
					<lower>0.0</lower>
					<upper>0.2</upper>
					<velocity>1</velocity>
					<effort>100000</effort>
				</limit>
			</axis>
		</joint>
		<joint name="piston6_prismatic_joint" type="prismatic">
			<parent>piston6_cylinder_link</parent>
			<child>piston6_shaft_linkL</child>
			<pose>0 0 0 0 0 0</pose>
			<axis>
				<xyz>0 0 1</xyz>
				<limit>
					<lower>0.0</lower>
					<upper>0.2</upper>
					<velocity>1</velocity>
					<effort>100000</effort>
				</limit>
			</axis>
		</joint>
		<joint name="bottom_ball1_joint" type="revolute">
			<parent>base_link</parent>
			<child>bottom_ball1_link</child>
			<pose>0 0 0 0 0 0</pose>
			<axis>
				<xyz>0 1 0</xyz>
				<limit>
					<lower>-0.5235987755982988</lower>
					<upper>0.5235987755982988</upper>
					<velocity>1</velocity>
					<effort/>
				</limit>
			</axis>
		</joint>
		<joint name="bottom_ball2_joint" type="revolute">
			<parent>base_link</parent>
			<child>bottom_ball2_link</child>
			<pose>0 0 0 0 0 0</pose>
			<axis>
				<xyz>0 1 0</xyz>
				<limit>
					<lower>-0.5235987755982988</lower>
					<upper>0.5235987755982988</upper>
					<velocity>1</velocity>
					<effort/>
				</limit>
			</axis>
		</joint>
		<joint name="bottom_ball3_joint" type="revolute">
			<parent>base_link</parent>
			<child>bottom_ball3_link</child>
			<pose>0 0 0 0 0 0</pose>
			<axis>
				<xyz>0 1 0</xyz>
				<limit>
					<lower>-0.5235987755982988</lower>
					<upper>0.5235987755982988</upper>
					<velocity>1</velocity>
					<effort/>
				</limit>
			</axis>
		</joint>
		<joint name="bottom_ball4_joint" type="revolute">
			<parent>base_link</parent>
			<child>bottom_ball4_link</child>
			<pose>0 0 0 0 0 0</pose>
			<axis>
				<xyz>0 1 0</xyz>
				<limit>
					<lower>-0.5235987755982988</lower>
					<upper>0.5235987755982988</upper>
					<velocity>1</velocity>
					<effort/>
				</limit>
			</axis>
		</joint>
		<joint name="bottom_ball5_joint" type="revolute">
			<parent>base_link</parent>
			<child>bottom_ball5_link</child>
			<pose>0 0 0 0 0 0</pose>
			<axis>
				<xyz>0 1 0</xyz>
				<limit>
					<lower>-0.5235987755982988</lower>
					<upper>0.5235987755982988</upper>
					<velocity>1</velocity>
					<effort/>
				</limit>
			</axis>
		</joint>
		<joint name="bottom_ball6_joint" type="revolute">
			<parent>base_link</parent>
			<child>bottom_ball6_link</child>
			<pose>0 0 0 0 0 0</pose>
			<axis>
				<xyz>0 1 0</xyz>
				<limit>
					<lower>-0.5235987755982988</lower>
					<upper>0.5235987755982988</upper>
					<velocity>1</velocity>
					<effort/>
				</limit>
			</axis>
		</joint>
		<joint name="piston1_bottom_pitch_joint" type="ball">
			<parent>bottom_ball1_link</parent>
			<child>piston1_cylinder_link</child>
			<pose>0 0 -0.13930713713011222 0 0 0</pose>
		</joint>
		<joint name="piston2_bottom_pitch_joint" type="ball">
			<parent>bottom_ball2_link</parent>
			<child>piston2_cylinder_link</child>
			<pose>0 0 -0.13930713713011222 0 0 0</pose>
		</joint>
		<joint name="piston3_bottom_pitch_joint" type="ball">
			<parent>bottom_ball3_link</parent>
			<child>piston3_cylinder_link</child>
			<pose>0 0 -0.13930713713011222 0 0 0</pose>
		</joint>
		<joint name="piston4_bottom_pitch_joint" type="ball">
			<parent>bottom_ball4_link</parent>
			<child>piston4_cylinder_link</child>
			<pose>0 0 -0.13930713713011222 0 0 0</pose>
		</joint>
		<joint name="piston5_bottom_pitch_joint" type="ball">
			<parent>bottom_ball5_link</parent>
			<child>piston5_cylinder_link</child>
			<pose>0 0 -0.13930713713011222 0 0 0</pose>
		</joint>
		<joint name="piston6_bottom_pitch_joint" type="ball">
			<parent>bottom_ball6_link</parent>
			<child>piston6_cylinder_link</child>
			<pose>0 0 -0.13930713713011222 0 0 0</pose>
		</joint>
		<joint name="top_ball1_joint" type="revolute">
			<parent>platform_link</parent>
			<child>top_ball1_link</child>
			<pose>0 0 0 0 0 0</pose>
			<axis>
				<xyz>0 1 0</xyz>
				<limit>
					<lower>-0.5235987755982988</lower>
					<upper>0.5235987755982988</upper>
					<velocity>1</velocity>
					<effort/>
				</limit>
			</axis>
			<axis2>
				<xyz>0 0 1</xyz>
				<limit>
					<lower>-0.5235987755982988</lower>
					<upper>0.5235987755982988</upper>
					<velocity>1</velocity>
					<effort/>
				</limit>
			</axis2>
		</joint>
		<joint name="top_ball2_joint" type="revolute">
			<parent>platform_link</parent>
			<child>top_ball2_link</child>
			<pose>0 0 0 0 0 0</pose>
			<axis>
				<xyz>0 1 0</xyz>
				<limit>
					<lower>-0.5235987755982988</lower>
					<upper>0.5235987755982988</upper>
					<velocity>1</velocity>
					<effort/>
				</limit>
			</axis>
			<axis2>
				<xyz>0 0 1</xyz>
				<limit>
					<lower>-0.5235987755982988</lower>
					<upper>0.5235987755982988</upper>
					<velocity>1</velocity>
					<effort/>
				</limit>
			</axis2>
		</joint>
		<joint name="top_ball3_joint" type="revolute">
			<parent>platform_link</parent>
			<child>top_ball3_link</child>
			<pose>0 0 0 0 0 0</pose>
			<axis>
				<xyz>0 1 0</xyz>
				<limit>
					<lower>-0.5235987755982988</lower>
					<upper>0.5235987755982988</upper>
					<velocity>1</velocity>
					<effort/>
				</limit>
			</axis>
			<axis2>
				<xyz>0 0 1</xyz>
				<limit>
					<lower>-0.5235987755982988</lower>
					<upper>0.5235987755982988</upper>
					<velocity>1</velocity>
					<effort/>
				</limit>
			</axis2>
		</joint>
		<joint name="top_ball4_joint" type="revolute">
			<parent>platform_link</parent>
			<child>top_ball4_link</child>
			<pose>0 0 0 0 0 0</pose>
			<axis>
				<xyz>0 1 0</xyz>
				<limit>
					<lower>-0.5235987755982988</lower>
					<upper>0.5235987755982988</upper>
					<velocity>1</velocity>
					<effort/>
				</limit>
			</axis>
			<axis2>
				<xyz>0 0 1</xyz>
				<limit>
					<lower>-0.5235987755982988</lower>
					<upper>0.5235987755982988</upper>
					<velocity>1</velocity>
					<effort/>
				</limit>
			</axis2>
		</joint>
		<joint name="top_ball5_joint" type="revolute">
			<parent>platform_link</parent>
			<child>top_ball5_link</child>
			<pose>0 0 0 0 0 0</pose>
			<axis>
				<xyz>0 1 0</xyz>
				<limit>
					<lower>-0.5235987755982988</lower>
					<upper>0.5235987755982988</upper>
					<velocity>1</velocity>
					<effort/>
				</limit>
			</axis>
			<axis2>
				<xyz>0 0 1</xyz>
				<limit>
					<lower>-0.5235987755982988</lower>
					<upper>0.5235987755982988</upper>
					<velocity>1</velocity>
					<effort/>
				</limit>
			</axis2>
		</joint>
		<joint name="top_ball6_joint" type="revolute">
			<parent>platform_link</parent>
			<child>top_ball6_link</child>
			<pose>0 0 0 0 0 0</pose>
			<axis>
				<xyz>0 1 0</xyz>
				<limit>
					<lower>-0.5235987755982988</lower>
					<upper>0.5235987755982988</upper>
					<velocity>1</velocity>
					<effort/>
				</limit>
			</axis>
			<axis2>
				<xyz>0 0 1</xyz>
				<limit>
					<lower>-0.5235987755982988</lower>
					<upper>0.5235987755982988</upper>
					<velocity>1</velocity>
					<effort/>
				</limit>
			</axis2>
		</joint>
		<joint name="piston1_top_pitch_joint" type="universal">
			<parent>top_ball1_link</parent>
			<child>piston1_shaft_linkU</child>
			<pose>0 0 0.13930713713011222 0 0 0</pose>
			<axis>
				<xyz>1 0 0</xyz>
				<limit>
					<lower>-0.5235987755982988</lower>
					<upper>0.5235987755982988</upper>
					<velocity/>
					<effort/>
				</limit>
			</axis>
		</joint>
		<joint name="piston2_top_pitch_joint" type="universal">
			<parent>top_ball2_link</parent>
			<child>piston2_shaft_linkU</child>
			<pose>0 0 0.13930713713011222 0 0 0</pose>
			<axis>
				<xyz>1 0 0</xyz>
				<limit>
					<lower>-0.5235987755982988</lower>
					<upper>0.5235987755982988</upper>
					<velocity/>
					<effort/>
				</limit>
			</axis>
		</joint>
		<joint name="piston3_top_pitch_joint" type="universal">
			<parent>top_ball3_link</parent>
			<child>piston3_shaft_linkU</child>
			<pose>0 0 0.13930713713011222 0 0 0</pose>
			<axis>
				<xyz>1 0 0</xyz>
				<limit>
					<lower>-0.5235987755982988</lower>
					<upper>0.5235987755982988</upper>
					<velocity/>
					<effort/>
				</limit>
			</axis>
		</joint>
		<joint name="piston4_top_pitch_joint" type="universal">
			<parent>top_ball4_link</parent>
			<child>piston4_shaft_linkU</child>
			<pose>0 0 0.13930713713011222 0 0 0</pose>
			<axis>
				<xyz>1 0 0</xyz>
				<limit>
					<lower>-0.5235987755982988</lower>
					<upper>0.5235987755982988</upper>
					<velocity/>
					<effort/>
				</limit>
			</axis>
		</joint>
		<joint name="piston5_top_pitch_joint" type="universal">
			<parent>top_ball5_link</parent>
			<child>piston5_shaft_linkU</child>
			<pose>0 0 0.13930713713011222 0 0 0</pose>
			<axis>
				<xyz>1 0 0</xyz>
				<limit>
					<lower>-0.5235987755982988</lower>
					<upper>0.5235987755982988</upper>
					<velocity/>
					<effort/>
				</limit>
			</axis>
		</joint>
		<joint name="piston6_top_pitch_joint" type="universal">
			<parent>top_ball6_link</parent>
			<child>piston6_shaft_linkU</child>
			<pose>0 0 0.13930713713011222 0 0 0</pose>
			<axis>
				<xyz>1 0 0</xyz>
				<limit>
					<lower>-0.5235987755982988</lower>
					<upper>0.5235987755982988</upper>
					<velocity/>
					<effort/>
				</limit>
			</axis>
		</joint>
		<link name="base_link">
			<pose>0 0 0.0005 0 0 0</pose>
			<gravity>0</gravity>
			<visual name="base_link_visual">
				<geometry>
					<cylinder>
						<radius>0.103</radius>
						<length>0.001</length>
					</cylinder>
				</geometry>
				<material>
					<script>
						<uri>file://media/materials/scripts/gazebo.material</uri>
						<name>Gazebo/Trunk</name>
					</script>
				</material>
			</visual>
			<collision name="base_link_collision">
				<geometry>
					<cylinder>
						<radius>0.103</radius>
						<length>0.001</length>
					</cylinder>
				</geometry>
			</collision>
		</link>
		<link name="platform_link">
			<pose>0 0 0.2705 0 0 0</pose>
			<gravity>0</gravity>
			<visual name="platform_link_visual">
				<geometry>
					<cylinder>
						<radius>0.0965</radius>
						<length>0.001</length>
					</cylinder>
				</geometry>
				<material>
					<script>
						<uri>file://media/materials/scripts/gazebo.material</uri>
						<name>Gazebo/Footway</name>
					</script>
				</material>
			</visual>
			<collision name="platform_link_collision">
				<geometry>
					<cylinder>
						<radius>0.0965</radius>
						<length>0.001</length>
					</cylinder>
				</geometry>
			</collision>
		</link>
		<link name="platform_cyl">
			<pose>0 0 0.29550000000000004 0 0 0</pose>
			<gravity>0</gravity>
			<visual name="platform_cyl_visual">
				<geometry>
					<cylinder>
						<radius>0.02</radius>
						<length>0.049</length>
					</cylinder>
				</geometry>
				<material>
					<script>
						<uri>file://media/materials/scripts/gazebo.material</uri>
						<name>Gazebo/Gold</name>
					</script>
				</material>
			</visual>
			<collision name="platform_cyl_collision">
				<geometry>
					<cylinder>
						<radius>0.02</radius>
						<length>0.049</length>
					</cylinder>
				</geometry>
			</collision>
		</link>
		<link name="platform_sphere">
			<pose>0 0 0.3405 0 0 0</pose>
			<gravity>0</gravity>
			<visual name="platform_sphere_visual">
				<geometry>
					<sphere>
						<radius>0.02</radius>
					</sphere>
				</geometry>
				<material>
					<script>
						<uri>file://media/materials/scripts/gazebo.material</uri>
						<name>Gazebo/Gold</name>
					</script>
				</material>
			</visual>
			<collision name="platform_sphere_collision">
				<geometry>
					<sphere>
						<radius>0.02</radius>
					</sphere>
				</geometry>
			</collision>
		</link>
		<joint name="plat_link_to_plat_cyl" type="fixed">
			<parent>platform_link</parent>
			<child>platform_cyl</child>
			<pose>0 0 0 0 0 0</pose>
		</joint>
		<joint name="plat_link_to_plat_sphere" type="fixed">
			<parent>platform_link</parent>
			<child>platform_sphere</child>
			<pose>0 0 0 0 0 0</pose>
		</joint>
		<link name="bottom_ball1_link">
			<pose>0.10143519856025741 0.017885762299693814 0.001 0 0 0.17453292519943286</pose>
			<gravity>0</gravity>
			<visual name="bottom_ball1_link_visual">
				<geometry>
					<sphere>
						<radius>0.0</radius>
					</sphere>
				</geometry>
				<material>
					<script>
						<uri>file://media/materials/scripts/gazebo.material</uri>
						<name>Gazebo/Gold</name>
					</script>
				</material>
			</visual>
		</link>
		<link name="bottom_ball2_link">
			<pose>-0.03522807476254387 0.09678833994094856 0.001 0 0 1.9198621771937625</pose>
			<gravity>0</gravity>
			<visual name="bottom_ball2_link_visual">
				<geometry>
					<sphere>
						<radius>0.0</radius>
					</sphere>
				</geometry>
				<material>
					<script>
						<uri>file://media/materials/scripts/gazebo.material</uri>
						<name>Gazebo/Gold</name>
					</script>
				</material>
			</visual>
		</link>
		<link name="bottom_ball3_link">
			<pose>-0.06620712379771355 0.07890257764125473 0.001 0 0 2.2689280275926285</pose>
			<gravity>0</gravity>
			<visual name="bottom_ball3_link_visual">
				<geometry>
					<sphere>
						<radius>0.0</radius>
					</sphere>
				</geometry>
				<material>
					<script>
						<uri>file://media/materials/scripts/gazebo.material</uri>
						<name>Gazebo/Gold</name>
					</script>
				</material>
			</visual>
		</link>
		<link name="bottom_ball4_link">
			<pose>-0.06620712379771357 -0.07890257764125472 0.001 0 0 -2.268928027592629</pose>
			<gravity>0</gravity>
			<visual name="bottom_ball4_link_visual">
				<geometry>
					<sphere>
						<radius>0.0</radius>
					</sphere>
				</geometry>
				<material>
					<script>
						<uri>file://media/materials/scripts/gazebo.material</uri>
						<name>Gazebo/Gold</name>
					</script>
				</material>
			</visual>
		</link>
		<link name="bottom_ball5_link">
			<pose>-0.03522807476254386 -0.09678833994094856 0.001 0 0 -1.9198621771937623</pose>
			<gravity>0</gravity>
			<visual name="bottom_ball5_link_visual">
				<geometry>
					<sphere>
						<radius>0.0</radius>
					</sphere>
				</geometry>
				<material>
					<script>
						<uri>file://media/materials/scripts/gazebo.material</uri>
						<name>Gazebo/Gold</name>
					</script>
				</material>
			</visual>
		</link>
		<link name="bottom_ball6_link">
			<pose>0.10143519856025741 -0.01788576229969383 0.001 0 0 -0.174532925199433</pose>
			<gravity>0</gravity>
			<visual name="bottom_ball6_link_visual">
				<geometry>
					<sphere>
						<radius>0.0</radius>
					</sphere>
				</geometry>
				<material>
					<script>
						<uri>file://media/materials/scripts/gazebo.material</uri>
						<name>Gazebo/Gold</name>
					</script>
				</material>
			</visual>
		</link>
		<link name="top_ball1_link">
			<pose>0.05874547789934154 0.07655859733810419 0.2695 0 0 0.916297857297023</pose>
			<gravity>0</gravity>
			<visual name="top_ball1_link_visual">
				<geometry>
					<sphere>
						<radius>0.0</radius>
					</sphere>
				</geometry>
				<material>
					<script>
						<uri>file://media/materials/scripts/gazebo.material</uri>
						<name>Gazebo/White</name>
					</script>
				</material>
			</visual>
		</link>
		<link name="top_ball2_link">
			<pose>0.03692895122323117 0.08915437488733917 0.2695 0 0 1.1780972450961724</pose>
			<gravity>0</gravity>
			<visual name="top_ball2_link_visual">
				<geometry>
					<sphere>
						<radius>0.0</radius>
					</sphere>
				</geometry>
				<material>
					<script>
						<uri>file://media/materials/scripts/gazebo.material</uri>
						<name>Gazebo/White</name>
					</script>
				</material>
			</visual>
		</link>
		<link name="top_ball3_link">
			<pose>-0.09567442912257271 0.012595777549234978 0.2695 0 0 3.0106929596902186</pose>
			<gravity>0</gravity>
			<visual name="top_ball3_link_visual">
				<geometry>
					<sphere>
						<radius>0.0</radius>
					</sphere>
				</geometry>
				<material>
					<script>
						<uri>file://media/materials/scripts/gazebo.material</uri>
						<name>Gazebo/White</name>
					</script>
				</material>
			</visual>
		</link>
		<link name="top_ball4_link">
			<pose>-0.09567442912257271 -0.012595777549234997 0.2695 0 0 -3.0106929596902186</pose>
			<gravity>0</gravity>
			<visual name="top_ball4_link_visual">
				<geometry>
					<sphere>
						<radius>0.0</radius>
					</sphere>
				</geometry>
				<material>
					<script>
						<uri>file://media/materials/scripts/gazebo.material</uri>
						<name>Gazebo/White</name>
					</script>
				</material>
			</visual>
		</link>
		<link name="top_ball5_link">
			<pose>0.036928951223231185 -0.08915437488733916 0.2695 0 0 -1.1780972450961722</pose>
			<gravity>0</gravity>
			<visual name="top_ball5_link_visual">
				<geometry>
					<sphere>
						<radius>0.0</radius>
					</sphere>
				</geometry>
				<material>
					<script>
						<uri>file://media/materials/scripts/gazebo.material</uri>
						<name>Gazebo/White</name>
					</script>
				</material>
			</visual>
		</link>
		<link name="top_ball6_link">
			<pose>0.058745477899341536 -0.07655859733810419 0.2695 0 0 -0.9162978572970231</pose>
			<gravity>0</gravity>
			<visual name="top_ball6_link_visual">
				<geometry>
					<sphere>
						<radius>0.0</radius>
					</sphere>
				</geometry>
				<material>
					<script>
						<uri>file://media/materials/scripts/gazebo.material</uri>
						<name>Gazebo/White</name>
					</script>
				</material>
			</visual>
		</link>
		<link name="piston1_cylinder_link">
			<pose>0.08009033822979948 0.047222179818899 0.1355 0 0.26346832695257616 2.199799567347474</pose>
			<gravity>0</gravity>
			<visual name="piston1_cylinder_link_visual">
				<geometry>
					<cylinder>
						<radius>0.005</radius>
						<length>0.27861427426022445</length>
					</cylinder>
				</geometry>
				<material>
					<script>
						<uri>file://media/materials/scripts/gazebo.material</uri>
						<name>Gazebo/Red</name>
					</script>
				</material>
			</visual>
		</link>
		<link name="piston2_cylinder_link">
			<pose>0.0008504382303436489 0.09297135741414386 0.1355 0 0.26346832695257616 -0.10540446495427867</pose>
			<gravity>0</gravity>
			<visual name="piston2_cylinder_link_visual">
				<geometry>
					<cylinder>
						<radius>0.005</radius>
						<length>0.27861427426022445</length>
					</cylinder>
				</geometry>
				<material>
					<script>
						<uri>file://media/materials/scripts/gazebo.material</uri>
						<name>Gazebo/Green</name>
					</script>
				</material>
			</visual>
		</link>
		<link name="piston3_cylinder_link">
			<pose>-0.08094077646014314 0.045749177595244855 0.1355 0 0.26346832695257616 -1.9889906374389168</pose>
			<gravity>0</gravity>
			<visual name="piston3_cylinder_link_visual">
				<geometry>
					<cylinder>
						<radius>0.005</radius>
						<length>0.27861427426022445</length>
					</cylinder>
				</geometry>
				<material>
					<script>
						<uri>file://media/materials/scripts/gazebo.material</uri>
						<name>Gazebo/Yellow</name>
					</script>
				</material>
			</visual>
		</link>
		<link name="piston4_cylinder_link">
			<pose>-0.08094077646014314 -0.045749177595244855 0.1355 0 0.26346832695257616 1.9889906374389168</pose>
			<gravity>0</gravity>
			<visual name="piston4_cylinder_link_visual">
				<geometry>
					<cylinder>
						<radius>0.005</radius>
						<length>0.27861427426022445</length>
					</cylinder>
				</geometry>
				<material>
					<script>
						<uri>file://media/materials/scripts/gazebo.material</uri>
						<name>Gazebo/Purple</name>
					</script>
				</material>
			</visual>
		</link>
		<link name="piston5_cylinder_link">
			<pose>0.0008504382303436628 -0.09297135741414386 0.1355 0 0.26346832695257616 0.10540446495427887</pose>
			<gravity>0</gravity>
			<visual name="piston5_cylinder_link_visual">
				<geometry>
					<cylinder>
						<radius>0.005</radius>
						<length>0.27861427426022445</length>
					</cylinder>
				</geometry>
				<material>
					<script>
						<uri>file://media/materials/scripts/gazebo.material</uri>
						<name>Gazebo/White</name>
					</script>
				</material>
			</visual>
		</link>
		<link name="piston6_cylinder_link">
			<pose>0.08009033822979947 -0.04722217981889901 0.1355 0 0.26346832695257616 -2.199799567347474</pose>
			<gravity>0</gravity>
			<visual name="piston6_cylinder_link_visual">
				<geometry>
					<cylinder>
						<radius>0.005</radius>
						<length>0.27861427426022445</length>
					</cylinder>
				</geometry>
				<material>
					<script>
						<uri>file://media/materials/scripts/gazebo.material</uri>
						<name>Gazebo/Blue</name>
					</script>
				</material>
			</visual>
		</link>
		<link name="piston1_shaft_linkU">
			<pose>0.08009033822979948 0.047222179818899 0.1355 0 0.26346832695257616 2.199799567347474</pose>
			<gravity>0</gravity>
			<visual name="piston1_shaft_linkU_visual">
				<geometry>
					<cylinder>
						<radius>0.0025</radius>
						<length>0.27861427426022445</length>
					</cylinder>
				</geometry>
				<material>
					<script>
						<uri>file://media/materials/scripts/gazebo.material</uri>
						<name>Gazebo/Black</name>
					</script>
				</material>
			</visual>
		</link>
		<link name="piston2_shaft_linkU">
			<pose>0.0008504382303436489 0.09297135741414386 0.1355 0 0.26346832695257616 -0.10540446495427867</pose>
			<gravity>0</gravity>
			<visual name="piston2_shaft_linkU_visual">
				<geometry>
					<cylinder>
						<radius>0.0025</radius>
						<length>0.27861427426022445</length>
					</cylinder>
				</geometry>
				<material>
					<script>
						<uri>file://media/materials/scripts/gazebo.material</uri>
						<name>Gazebo/Black</name>
					</script>
				</material>
			</visual>
		</link>
		<link name="piston3_shaft_linkU">
			<pose>-0.08094077646014314 0.045749177595244855 0.1355 0 0.26346832695257616 -1.9889906374389168</pose>
			<gravity>0</gravity>
			<visual name="piston3_shaft_linkU_visual">
				<geometry>
					<cylinder>
						<radius>0.0025</radius>
						<length>0.27861427426022445</length>
					</cylinder>
				</geometry>
				<material>
					<script>
						<uri>file://media/materials/scripts/gazebo.material</uri>
						<name>Gazebo/Black</name>
					</script>
				</material>
			</visual>
		</link>
		<link name="piston4_shaft_linkU">
			<pose>-0.08094077646014314 -0.045749177595244855 0.1355 0 0.26346832695257616 1.9889906374389168</pose>
			<gravity>0</gravity>
			<visual name="piston4_shaft_linkU_visual">
				<geometry>
					<cylinder>
						<radius>0.0025</radius>
						<length>0.27861427426022445</length>
					</cylinder>
				</geometry>
				<material>
					<script>
						<uri>file://media/materials/scripts/gazebo.material</uri>
						<name>Gazebo/Black</name>
					</script>
				</material>
			</visual>
		</link>
		<link name="piston5_shaft_linkU">
			<pose>0.0008504382303436628 -0.09297135741414386 0.1355 0 0.26346832695257616 0.10540446495427887</pose>
			<gravity>0</gravity>
			<visual name="piston5_shaft_linkU_visual">
				<geometry>
					<cylinder>
						<radius>0.0025</radius>
						<length>0.27861427426022445</length>
					</cylinder>
				</geometry>
				<material>
					<script>
						<uri>file://media/materials/scripts/gazebo.material</uri>
						<name>Gazebo/Black</name>
					</script>
				</material>
			</visual>
		</link>
		<link name="piston6_shaft_linkU">
			<pose>0.08009033822979947 -0.04722217981889901 0.1355 0 0.26346832695257616 -2.199799567347474</pose>
			<gravity>0</gravity>
			<visual name="piston6_shaft_linkU_visual">
				<geometry>
					<cylinder>
						<radius>0.0025</radius>
						<length>0.27861427426022445</length>
					</cylinder>
				</geometry>
				<material>
					<script>
						<uri>file://media/materials/scripts/gazebo.material</uri>
						<name>Gazebo/Black</name>
					</script>
				</material>
			</visual>
		</link>
		<link name="piston1_shaft_linkL">
			<pose>0.08009033822979948 0.047222179818899 0.1355 0 0.26346832695257616 2.199799567347474</pose>
			<gravity>0</gravity>
			<visual name="piston1_shaft_linkL_visual">
				<geometry>
					<cylinder>
						<radius>0.0025</radius>
						<length>0.27861427426022445</length>
					</cylinder>
				</geometry>
				<material>
					<script>
						<uri>file://media/materials/scripts/gazebo.material</uri>
						<name>Gazebo/Black</name>
					</script>
				</material>
			</visual>
		</link>
		<link name="piston2_shaft_linkL">
			<pose>0.0008504382303436489 0.09297135741414386 0.1355 0 0.26346832695257616 -0.10540446495427867</pose>
			<gravity>0</gravity>
			<visual name="piston2_shaft_linkL_visual">
				<geometry>
					<cylinder>
						<radius>0.0025</radius>
						<length>0.27861427426022445</length>
					</cylinder>
				</geometry>
				<material>
					<script>
						<uri>file://media/materials/scripts/gazebo.material</uri>
						<name>Gazebo/Black</name>
					</script>
				</material>
			</visual>
		</link>
		<link name="piston3_shaft_linkL">
			<pose>-0.08094077646014314 0.045749177595244855 0.1355 0 0.26346832695257616 -1.9889906374389168</pose>
			<gravity>0</gravity>
			<visual name="piston3_shaft_linkL_visual">
				<geometry>
					<cylinder>
						<radius>0.0025</radius>
						<length>0.27861427426022445</length>
					</cylinder>
				</geometry>
				<material>
					<script>
						<uri>file://media/materials/scripts/gazebo.material</uri>
						<name>Gazebo/Black</name>
					</script>
				</material>
			</visual>
		</link>
		<link name="piston4_shaft_linkL">
			<pose>-0.08094077646014314 -0.045749177595244855 0.1355 0 0.26346832695257616 1.9889906374389168</pose>
			<gravity>0</gravity>
			<visual name="piston4_shaft_linkL_visual">
				<geometry>
					<cylinder>
						<radius>0.0025</radius>
						<length>0.27861427426022445</length>
					</cylinder>
				</geometry>
				<material>
					<script>
						<uri>file://media/materials/scripts/gazebo.material</uri>
						<name>Gazebo/Black</name>
					</script>
				</material>
			</visual>
		</link>
		<link name="piston5_shaft_linkL">
			<pose>0.0008504382303436628 -0.09297135741414386 0.1355 0 0.26346832695257616 0.10540446495427887</pose>
			<gravity>0</gravity>
			<visual name="piston5_shaft_linkL_visual">
				<geometry>
					<cylinder>
						<radius>0.0025</radius>
						<length>0.27861427426022445</length>
					</cylinder>
				</geometry>
				<material>
					<script>
						<uri>file://media/materials/scripts/gazebo.material</uri>
						<name>Gazebo/Black</name>
					</script>
				</material>
			</visual>
		</link>
		<link name="piston6_shaft_linkL">
			<pose>0.08009033822979947 -0.04722217981889901 0.1355 0 0.26346832695257616 -2.199799567347474</pose>
			<gravity>0</gravity>
			<visual name="piston6_shaft_linkL_visual">
				<geometry>
					<cylinder>
						<radius>0.0025</radius>
						<length>0.27861427426022445</length>
					</cylinder>
				</geometry>
				<material>
					<script>
						<uri>file://media/materials/scripts/gazebo.material</uri>
						<name>Gazebo/Black</name>
					</script>
				</material>
			</visual>
		</link>
		<plugin filename="libgz-sim-detachable-joint-system.so" name="gz::sim::systems::DetachableJoint">
			<parent_link>piston1_shaft_linkL</parent_link>
			<child_link>piston1_shaft_linkU</child_link>
			<child_model>stewart</child_model>
		</plugin>
		<plugin filename="libgz-sim-detachable-joint-system.so" name="gz::sim::systems::DetachableJoint">
			<parent_link>piston2_shaft_linkL</parent_link>
			<child_link>piston2_shaft_linkU</child_link>
			<child_model>stewart</child_model>
		</plugin>
		<plugin filename="libgz-sim-detachable-joint-system.so" name="gz::sim::systems::DetachableJoint">
			<parent_link>piston3_shaft_linkL</parent_link>
			<child_link>piston3_shaft_linkU</child_link>
			<child_model>stewart</child_model>
		</plugin>
		<plugin filename="libgz-sim-detachable-joint-system.so" name="gz::sim::systems::DetachableJoint">
			<parent_link>piston4_shaft_linkL</parent_link>
			<child_link>piston4_shaft_linkU</child_link>
			<child_model>stewart</child_model>
		</plugin>
		<plugin filename="libgz-sim-detachable-joint-system.so" name="gz::sim::systems::DetachableJoint">
			<parent_link>piston5_shaft_linkL</parent_link>
			<child_link>piston5_shaft_linkU</child_link>
			<child_model>stewart</child_model>
		</plugin>
		<plugin filename="libgz-sim-detachable-joint-system.so" name="gz::sim::systems::DetachableJoint">
			<parent_link>piston6_shaft_linkL</parent_link>
			<child_link>piston6_shaft_linkU</child_link>
			<child_model>stewart</child_model>
		</plugin>
		<plugin filename="gz-sim-joint-position-controller-system" name="gz::sim::systems::JointPositionController">
			<joint_name>piston1_prismatic_joint</joint_name>
			<p_gain>50000</p_gain>
			<i_gain>10000</i_gain>
			<d_gain>1000</d_gain>
		</plugin>
		<plugin filename="gz-sim-joint-position-controller-system" name="gz::sim::systems::JointPositionController">
			<joint_name>piston2_prismatic_joint</joint_name>
			<p_gain>50000</p_gain>
			<i_gain>10000</i_gain>
			<d_gain>1000</d_gain>
		</plugin>
		<plugin filename="gz-sim-joint-position-controller-system" name="gz::sim::systems::JointPositionController">
			<joint_name>piston3_prismatic_joint</joint_name>
			<p_gain>50000</p_gain>
			<i_gain>10000</i_gain>
			<d_gain>1000</d_gain>
		</plugin>
		<plugin filename="gz-sim-joint-position-controller-system" name="gz::sim::systems::JointPositionController">
			<joint_name>piston4_prismatic_joint</joint_name>
			<p_gain>50000</p_gain>
			<i_gain>10000</i_gain>
			<d_gain>1000</d_gain>
		</plugin>
		<plugin filename="gz-sim-joint-position-controller-system" name="gz::sim::systems::JointPositionController">
			<joint_name>piston5_prismatic_joint</joint_name>
			<p_gain>50000</p_gain>
			<i_gain>10000</i_gain>
			<d_gain>1000</d_gain>
		</plugin>
		<plugin filename="gz-sim-joint-position-controller-system" name="gz::sim::systems::JointPositionController">
			<joint_name>piston6_prismatic_joint</joint_name>
			<p_gain>50000</p_gain>
			<i_gain>10000</i_gain>
			<d_gain>1000</d_gain>
		</plugin>
	</model>
</sdf>
