<?xml version="1.0" ?>
<sdf version="1.5">
	<model name="stewart">
		<plugin name="gz::sim::systems::PosePublisher" filename="gz-sim-pose-publisher-system">
			<publish_link_pose>true</publish_link_pose>
			<use_pose_vector_msg>true</use_pose_vector_msg>
			<static_publisher>false</static_publisher>
			<static_update_frequency>1</static_update_frequency>
		</plugin>
		<plugin name="gz::sim::systems::JointStatePublisher" filename="gz-sim-joint-state-publisher-system"/>
		<joint name="piston1_prismatic_joint" type="prismatic">
			<parent>piston1_cylinder_link</parent>
			<child>piston1_shaft_linkL</child>
			<pose>0 0 0 0 0 0</pose>
			<axis>
				<xyz>0 0 1</xyz>
				<limit>
					<lower>0.0</lower>
					<upper>0.2</upper>
					<velocity>1</velocity>
					<effort>100000</effort>
				</limit>
			</axis>
		</joint>
		<joint name="piston2_prismatic_joint" type="prismatic">
			<parent>piston2_cylinder_link</parent>
			<child>piston2_shaft_linkL</child>
			<pose>0 0 0 0 0 0</pose>
			<axis>
				<xyz>0 0 1</xyz>
				<limit>
					<lower>0.0</lower>
					<upper>0.2</upper>
					<velocity>1</velocity>
					<effort>100000</effort>
				</limit>
			</axis>
		</joint>
		<joint name="piston3_prismatic_joint" type="prismatic">
			<parent>piston3_cylinder_link</parent>
			<child>piston3_shaft_linkL</child>
			<pose>0 0 0 0 0 0</pose>
			<axis>
				<xyz>0 0 1</xyz>
				<limit>
					<lower>0.0</lower>
					<upper>0.2</upper>
					<velocity>1</velocity>
					<effort>100000</effort>
				</limit>
			</axis>
		</joint>
		<joint name="piston4_prismatic_joint" type="prismatic">
			<parent>piston4_cylinder_link</parent>
			<child>piston4_shaft_linkL</child>
			<pose>0 0 0 0 0 0</pose>
			<axis>
				<xyz>0 0 1</xyz>
				<limit>
					<lower>0.0</lower>
					<upper>0.2</upper>
					<velocity>1</velocity>
					<effort>100000</effort>
				</limit>
			</axis>
		</joint>
		<joint name="piston5_prismatic_joint" type="prismatic">
			<parent>piston5_cylinder_link</parent>
			<child>piston5_shaft_linkL</child>
			<pose>0 0 0 0 0 0</pose>
			<axis>
				<xyz>0 0 1</xyz>
				<limit>
					<lower>0.0</lower>
					<upper>0.2</upper>
					<velocity>1</velocity>
					<effort>100000</effort>
				</limit>
			</axis>
		</joint>
		<joint name="piston6_prismatic_joint" type="prismatic">
			<parent>piston6_cylinder_link</parent>
			<child>piston6_shaft_linkL</child>
			<pose>0 0 0 0 0 0</pose>
			<axis>
				<xyz>0 0 1</xyz>
				<limit>
					<lower>0.0</lower>
					<upper>0.2</upper>
					<velocity>1</velocity>
					<effort>100000</effort>
				</limit>
			</axis>
		</joint>
		<joint name="bottom_ball1_joint" type="revolute">
			<parent>base_link</parent>
			<child>bottom_ball1_link</child>
			<pose>0 0 0 0 0 0</pose>
			<axis>
				<xyz>0 1 0</xyz>
				<limit>
					<lower>-0.5235987755982988</lower>
					<upper>0.5235987755982988</upper>
					<velocity>1</velocity>
					<effort/>
				</limit>
			</axis>
		</joint>
		<joint name="bottom_ball2_joint" type="revolute">
			<parent>base_link</parent>
			<child>bottom_ball2_link</child>
			<pose>0 0 0 0 0 0</pose>
			<axis>
				<xyz>0 1 0</xyz>
				<limit>
					<lower>-0.5235987755982988</lower>
					<upper>0.5235987755982988</upper>
					<velocity>1</velocity>
					<effort/>
				</limit>
			</axis>
		</joint>
		<joint name="bottom_ball3_joint" type="revolute">
			<parent>base_link</parent>
			<child>bottom_ball3_link</child>
			<pose>0 0 0 0 0 0</pose>
			<axis>
				<xyz>0 1 0</xyz>
				<limit>
					<lower>-0.5235987755982988</lower>
					<upper>0.5235987755982988</upper>
					<velocity>1</velocity>
					<effort/>
				</limit>
			</axis>
		</joint>
		<joint name="bottom_ball4_joint" type="revolute">
			<parent>base_link</parent>
			<child>bottom_ball4_link</child>
			<pose>0 0 0 0 0 0</pose>
			<axis>
				<xyz>0 1 0</xyz>
				<limit>
					<lower>-0.5235987755982988</lower>
					<upper>0.5235987755982988</upper>
					<velocity>1</velocity>
					<effort/>
				</limit>
			</axis>
		</joint>
		<joint name="bottom_ball5_joint" type="revolute">
			<parent>base_link</parent>
			<child>bottom_ball5_link</child>
			<pose>0 0 0 0 0 0</pose>
			<axis>
				<xyz>0 1 0</xyz>
				<limit>
					<lower>-0.5235987755982988</lower>
					<upper>0.5235987755982988</upper>
					<velocity>1</velocity>
					<effort/>
				</limit>
			</axis>
		</joint>
		<joint name="bottom_ball6_joint" type="revolute">
			<parent>base_link</parent>
			<child>bottom_ball6_link</child>
			<pose>0 0 0 0 0 0</pose>
			<axis>
				<xyz>0 1 0</xyz>
				<limit>
					<lower>-0.5235987755982988</lower>
					<upper>0.5235987755982988</upper>
					<velocity>1</velocity>
					<effort/>
				</limit>
			</axis>
		</joint>
		<joint name="piston1_bottom_pitch_joint" type="ball">
			<parent>bottom_ball1_link</parent>
			<child>piston1_cylinder_link</child>
			<pose>0 0 -0.1085283145030097 0 0 0</pose>
		</joint>
		<joint name="piston2_bottom_pitch_joint" type="ball">
			<parent>bottom_ball2_link</parent>
			<child>piston2_cylinder_link</child>
			<pose>0 0 -0.1085283145030097 0 0 0</pose>
		</joint>
		<joint name="piston3_bottom_pitch_joint" type="ball">
			<parent>bottom_ball3_link</parent>
			<child>piston3_cylinder_link</child>
			<pose>0 0 -0.1085283145030097 0 0 0</pose>
		</joint>
		<joint name="piston4_bottom_pitch_joint" type="ball">
			<parent>bottom_ball4_link</parent>
			<child>piston4_cylinder_link</child>
			<pose>0 0 -0.1085283145030097 0 0 0</pose>
		</joint>
		<joint name="piston5_bottom_pitch_joint" type="ball">
			<parent>bottom_ball5_link</parent>
			<child>piston5_cylinder_link</child>
			<pose>0 0 -0.1085283145030097 0 0 0</pose>
		</joint>
		<joint name="piston6_bottom_pitch_joint" type="ball">
			<parent>bottom_ball6_link</parent>
			<child>piston6_cylinder_link</child>
			<pose>0 0 -0.1085283145030097 0 0 0</pose>
		</joint>
		<joint name="top_ball1_joint" type="revolute">
			<parent>platform_link</parent>
			<child>top_ball1_link</child>
			<pose>0 0 0 0 0 0</pose>
			<axis>
				<xyz>0 1 0</xyz>
				<limit>
					<lower>-0.5235987755982988</lower>
					<upper>0.5235987755982988</upper>
					<velocity>1</velocity>
					<effort/>
				</limit>
			</axis>
			<axis2>
				<xyz>0 0 1</xyz>
				<limit>
					<lower>-0.5235987755982988</lower>
					<upper>0.5235987755982988</upper>
					<velocity>1</velocity>
					<effort/>
				</limit>
			</axis2>
		</joint>
		<joint name="top_ball2_joint" type="revolute">
			<parent>platform_link</parent>
			<child>top_ball2_link</child>
			<pose>0 0 0 0 0 0</pose>
			<axis>
				<xyz>0 1 0</xyz>
				<limit>
					<lower>-0.5235987755982988</lower>
					<upper>0.5235987755982988</upper>
					<velocity>1</velocity>
					<effort/>
				</limit>
			</axis>
			<axis2>
				<xyz>0 0 1</xyz>
				<limit>
					<lower>-0.5235987755982988</lower>
					<upper>0.5235987755982988</upper>
					<velocity>1</velocity>
					<effort/>
				</limit>
			</axis2>
		</joint>
		<joint name="top_ball3_joint" type="revolute">
			<parent>platform_link</parent>
			<child>top_ball3_link</child>
			<pose>0 0 0 0 0 0</pose>
			<axis>
				<xyz>0 1 0</xyz>
				<limit>
					<lower>-0.5235987755982988</lower>
					<upper>0.5235987755982988</upper>
					<velocity>1</velocity>
					<effort/>
				</limit>
			</axis>
			<axis2>
				<xyz>0 0 1</xyz>
				<limit>
					<lower>-0.5235987755982988</lower>
					<upper>0.5235987755982988</upper>
					<velocity>1</velocity>
					<effort/>
				</limit>
			</axis2>
		</joint>
		<joint name="top_ball4_joint" type="revolute">
			<parent>platform_link</parent>
			<child>top_ball4_link</child>
			<pose>0 0 0 0 0 0</pose>
			<axis>
				<xyz>0 1 0</xyz>
				<limit>
					<lower>-0.5235987755982988</lower>
					<upper>0.5235987755982988</upper>
					<velocity>1</velocity>
					<effort/>
				</limit>
			</axis>
			<axis2>
				<xyz>0 0 1</xyz>
				<limit>
					<lower>-0.5235987755982988</lower>
					<upper>0.5235987755982988</upper>
					<velocity>1</velocity>
					<effort/>
				</limit>
			</axis2>
		</joint>
		<joint name="top_ball5_joint" type="revolute">
			<parent>platform_link</parent>
			<child>top_ball5_link</child>
			<pose>0 0 0 0 0 0</pose>
			<axis>
				<xyz>0 1 0</xyz>
				<limit>
					<lower>-0.5235987755982988</lower>
					<upper>0.5235987755982988</upper>
					<velocity>1</velocity>
					<effort/>
				</limit>
			</axis>
			<axis2>
				<xyz>0 0 1</xyz>
				<limit>
					<lower>-0.5235987755982988</lower>
					<upper>0.5235987755982988</upper>
					<velocity>1</velocity>
					<effort/>
				</limit>
			</axis2>
		</joint>
		<joint name="top_ball6_joint" type="revolute">
			<parent>platform_link</parent>
			<child>top_ball6_link</child>
			<pose>0 0 0 0 0 0</pose>
			<axis>
				<xyz>0 1 0</xyz>
				<limit>
					<lower>-0.5235987755982988</lower>
					<upper>0.5235987755982988</upper>
					<velocity>1</velocity>
					<effort/>
				</limit>
			</axis>
			<axis2>
				<xyz>0 0 1</xyz>
				<limit>
					<lower>-0.5235987755982988</lower>
					<upper>0.5235987755982988</upper>
					<velocity>1</velocity>
					<effort/>
				</limit>
			</axis2>
		</joint>
		<joint name="piston1_top_pitch_joint" type="universal">
			<parent>top_ball1_link</parent>
			<child>piston1_shaft_linkU</child>
			<pose>0 0 0.1085283145030097 0 0 0</pose>
			<axis>
				<xyz>1 0 0</xyz>
				<limit>
					<lower>-0.5235987755982988</lower>
					<upper>0.5235987755982988</upper>
					<velocity/>
					<effort/>
				</limit>
			</axis>
		</joint>
		<joint name="piston2_top_pitch_joint" type="universal">
			<parent>top_ball2_link</parent>
			<child>piston2_shaft_linkU</child>
			<pose>0 0 0.1085283145030097 0 0 0</pose>
			<axis>
				<xyz>1 0 0</xyz>
				<limit>
					<lower>-0.5235987755982988</lower>
					<upper>0.5235987755982988</upper>
					<velocity/>
					<effort/>
				</limit>
			</axis>
		</joint>
		<joint name="piston3_top_pitch_joint" type="universal">
			<parent>top_ball3_link</parent>
			<child>piston3_shaft_linkU</child>
			<pose>0 0 0.1085283145030097 0 0 0</pose>
			<axis>
				<xyz>1 0 0</xyz>
				<limit>
					<lower>-0.5235987755982988</lower>
					<upper>0.5235987755982988</upper>
					<velocity/>
					<effort/>
				</limit>
			</axis>
		</joint>
		<joint name="piston4_top_pitch_joint" type="universal">
			<parent>top_ball4_link</parent>
			<child>piston4_shaft_linkU</child>
			<pose>0 0 0.1085283145030097 0 0 0</pose>
			<axis>
				<xyz>1 0 0</xyz>
				<limit>
					<lower>-0.5235987755982988</lower>
					<upper>0.5235987755982988</upper>
					<velocity/>
					<effort/>
				</limit>
			</axis>
		</joint>
		<joint name="piston5_top_pitch_joint" type="universal">
			<parent>top_ball5_link</parent>
			<child>piston5_shaft_linkU</child>
			<pose>0 0 0.1085283145030097 0 0 0</pose>
			<axis>
				<xyz>1 0 0</xyz>
				<limit>
					<lower>-0.5235987755982988</lower>
					<upper>0.5235987755982988</upper>
					<velocity/>
					<effort/>
				</limit>
			</axis>
		</joint>
		<joint name="piston6_top_pitch_joint" type="universal">
			<parent>top_ball6_link</parent>
			<child>piston6_shaft_linkU</child>
			<pose>0 0 0.1085283145030097 0 0 0</pose>
			<axis>
				<xyz>1 0 0</xyz>
				<limit>
					<lower>-0.5235987755982988</lower>
					<upper>0.5235987755982988</upper>
					<velocity/>
					<effort/>
				</limit>
			</axis>
		</joint>
		<link name="base_link">
			<pose>0 0 0.0075 0 0 0</pose>
			<gravity>0</gravity>
			<visual name="base_link_visual">
				<geometry>
					<cylinder>
						<radius>0.103</radius>
						<length>0.015</length>
					</cylinder>
				</geometry>
				<material>
					<script>
						<uri>file://media/materials/scripts/gazebo.material</uri>
						<name>Gazebo/Trunk</name>
					</script>
				</material>
			</visual>
			<collision name="base_link_collision">
				<geometry>
					<cylinder>
						<radius>0.103</radius>
						<length>0.015</length>
					</cylinder>
				</geometry>
			</collision>
		</link>
		<link name="platform_link">
			<pose>0 0 0.2575 0 0 0</pose>
			<gravity>0</gravity>
			<visual name="platform_link_visual">
				<geometry>
					<cylinder>
						<radius>0.0965</radius>
						<length>0.015</length>
					</cylinder>
				</geometry>
				<material>
					<script>
						<uri>file://media/materials/scripts/gazebo.material</uri>
						<name>Gazebo/Footway</name>
					</script>
				</material>
			</visual>
			<collision name="platform_link_collision">
				<geometry>
					<cylinder>
						<radius>0.0965</radius>
						<length>0.015</length>
					</cylinder>
				</geometry>
			</collision>
		</link>
		<link name="bottom_ball1_link">
			<pose>0.09129167870423167 0.016097186069724434 0.015 0 0 0.1745329251994329</pose>
			<gravity>0</gravity>
			<visual name="bottom_ball1_link_visual">
				<geometry>
					<sphere>
						<radius>0.018</radius>
					</sphere>
				</geometry>
				<material>
					<script>
						<uri>file://media/materials/scripts/gazebo.material</uri>
						<name>Gazebo/Gold</name>
					</script>
				</material>
			</visual>
		</link>
		<link name="bottom_ball2_link">
			<pose>-0.03170526728628949 0.0871095059468537 0.015 0 0 1.9198621771937625</pose>
			<gravity>0</gravity>
			<visual name="bottom_ball2_link_visual">
				<geometry>
					<sphere>
						<radius>0.018</radius>
					</sphere>
				</geometry>
				<material>
					<script>
						<uri>file://media/materials/scripts/gazebo.material</uri>
						<name>Gazebo/Gold</name>
					</script>
				</material>
			</visual>
		</link>
		<link name="bottom_ball3_link">
			<pose>-0.059586411417942194 0.07101231987712925 0.015 0 0 2.2689280275926285</pose>
			<gravity>0</gravity>
			<visual name="bottom_ball3_link_visual">
				<geometry>
					<sphere>
						<radius>0.018</radius>
					</sphere>
				</geometry>
				<material>
					<script>
						<uri>file://media/materials/scripts/gazebo.material</uri>
						<name>Gazebo/Gold</name>
					</script>
				</material>
			</visual>
		</link>
		<link name="bottom_ball4_link">
			<pose>-0.0595864114179422 -0.07101231987712925 0.015 0 0 -2.2689280275926285</pose>
			<gravity>0</gravity>
			<visual name="bottom_ball4_link_visual">
				<geometry>
					<sphere>
						<radius>0.018</radius>
					</sphere>
				</geometry>
				<material>
					<script>
						<uri>file://media/materials/scripts/gazebo.material</uri>
						<name>Gazebo/Gold</name>
					</script>
				</material>
			</visual>
		</link>
		<link name="bottom_ball5_link">
			<pose>-0.031705267286289474 -0.0871095059468537 0.015 0 0 -1.9198621771937623</pose>
			<gravity>0</gravity>
			<visual name="bottom_ball5_link_visual">
				<geometry>
					<sphere>
						<radius>0.018</radius>
					</sphere>
				</geometry>
				<material>
					<script>
						<uri>file://media/materials/scripts/gazebo.material</uri>
						<name>Gazebo/Gold</name>
					</script>
				</material>
			</visual>
		</link>
		<link name="bottom_ball6_link">
			<pose>0.09129167870423167 -0.016097186069724444 0.015 0 0 -0.174532925199433</pose>
			<gravity>0</gravity>
			<visual name="bottom_ball6_link_visual">
				<geometry>
					<sphere>
						<radius>0.018</radius>
					</sphere>
				</geometry>
				<material>
					<script>
						<uri>file://media/materials/scripts/gazebo.material</uri>
						<name>Gazebo/Gold</name>
					</script>
				</material>
			</visual>
		</link>
		<link name="top_ball1_link">
			<pose>0.05287093010940739 0.06890273760429377 0.2425 0 0 0.916297857297023</pose>
			<gravity>0</gravity>
			<visual name="top_ball1_link_visual">
				<geometry>
					<sphere>
						<radius>0.01</radius>
					</sphere>
				</geometry>
				<material>
					<script>
						<uri>file://media/materials/scripts/gazebo.material</uri>
						<name>Gazebo/White</name>
					</script>
				</material>
			</visual>
		</link>
		<link name="top_ball2_link">
			<pose>0.03323605610090805 0.08023893739860526 0.2425 0 0 1.1780972450961724</pose>
			<gravity>0</gravity>
			<visual name="top_ball2_link_visual">
				<geometry>
					<sphere>
						<radius>0.01</radius>
					</sphere>
				</geometry>
				<material>
					<script>
						<uri>file://media/materials/scripts/gazebo.material</uri>
						<name>Gazebo/White</name>
					</script>
				</material>
			</visual>
		</link>
		<link name="top_ball3_link">
			<pose>-0.08610698621031543 0.01133619979431148 0.2425 0 0 3.0106929596902186</pose>
			<gravity>0</gravity>
			<visual name="top_ball3_link_visual">
				<geometry>
					<sphere>
						<radius>0.01</radius>
					</sphere>
				</geometry>
				<material>
					<script>
						<uri>file://media/materials/scripts/gazebo.material</uri>
						<name>Gazebo/White</name>
					</script>
				</material>
			</visual>
		</link>
		<link name="top_ball4_link">
			<pose>-0.08610698621031543 -0.011336199794311495 0.2425 0 0 -3.0106929596902186</pose>
			<gravity>0</gravity>
			<visual name="top_ball4_link_visual">
				<geometry>
					<sphere>
						<radius>0.01</radius>
					</sphere>
				</geometry>
				<material>
					<script>
						<uri>file://media/materials/scripts/gazebo.material</uri>
						<name>Gazebo/White</name>
					</script>
				</material>
			</visual>
		</link>
		<link name="top_ball5_link">
			<pose>0.03323605610090807 -0.08023893739860524 0.2425 0 0 -1.1780972450961722</pose>
			<gravity>0</gravity>
			<visual name="top_ball5_link_visual">
				<geometry>
					<sphere>
						<radius>0.01</radius>
					</sphere>
				</geometry>
				<material>
					<script>
						<uri>file://media/materials/scripts/gazebo.material</uri>
						<name>Gazebo/White</name>
					</script>
				</material>
			</visual>
		</link>
		<link name="top_ball6_link">
			<pose>0.052870930109407376 -0.06890273760429377 0.2425 0 0 -0.9162978572970232</pose>
			<gravity>0</gravity>
			<visual name="top_ball6_link_visual">
				<geometry>
					<sphere>
						<radius>0.01</radius>
					</sphere>
				</geometry>
				<material>
					<script>
						<uri>file://media/materials/scripts/gazebo.material</uri>
						<name>Gazebo/White</name>
					</script>
				</material>
			</visual>
		</link>
		<link name="piston1_cylinder_link">
			<pose>0.07208130440681954 0.042499961837009104 0.1365 0 0.30559477021812076 2.199799567347474</pose>
			<gravity>0</gravity>
			<visual name="piston1_cylinder_link_visual">
				<geometry>
					<cylinder>
						<radius>0.009</radius>
						<length>0.2170566290060194</length>
					</cylinder>
				</geometry>
				<material>
					<script>
						<uri>file://media/materials/scripts/gazebo.material</uri>
						<name>Gazebo/Red</name>
					</script>
				</material>
			</visual>
		</link>
		<link name="piston2_cylinder_link">
			<pose>0.0007653944073092826 0.08367422167272948 0.1365 0 0.305594770218121 -0.10540446495427853</pose>
			<gravity>0</gravity>
			<visual name="piston2_cylinder_link_visual">
				<geometry>
					<cylinder>
						<radius>0.009</radius>
						<length>0.2170566290060194</length>
					</cylinder>
				</geometry>
				<material>
					<script>
						<uri>file://media/materials/scripts/gazebo.material</uri>
						<name>Gazebo/Green</name>
					</script>
				</material>
			</visual>
		</link>
		<link name="piston3_cylinder_link">
			<pose>-0.07284669881412881 0.041174259835720366 0.1365 0 0.30559477021812076 -1.9889906374389168</pose>
			<gravity>0</gravity>
			<visual name="piston3_cylinder_link_visual">
				<geometry>
					<cylinder>
						<radius>0.009</radius>
						<length>0.2170566290060194</length>
					</cylinder>
				</geometry>
				<material>
					<script>
						<uri>file://media/materials/scripts/gazebo.material</uri>
						<name>Gazebo/Yellow</name>
					</script>
				</material>
			</visual>
		</link>
		<link name="piston4_cylinder_link">
			<pose>-0.07284669881412881 -0.04117425983572037 0.1365 0 0.30559477021812076 1.9889906374389168</pose>
			<gravity>0</gravity>
			<visual name="piston4_cylinder_link_visual">
				<geometry>
					<cylinder>
						<radius>0.009</radius>
						<length>0.2170566290060194</length>
					</cylinder>
				</geometry>
				<material>
					<script>
						<uri>file://media/materials/scripts/gazebo.material</uri>
						<name>Gazebo/Purple</name>
					</script>
				</material>
			</visual>
		</link>
		<link name="piston5_cylinder_link">
			<pose>0.0007653944073092965 -0.08367422167272948 0.1365 0 0.305594770218121 0.10540446495427876</pose>
			<gravity>0</gravity>
			<visual name="piston5_cylinder_link_visual">
				<geometry>
					<cylinder>
						<radius>0.009</radius>
						<length>0.2170566290060194</length>
					</cylinder>
				</geometry>
				<material>
					<script>
						<uri>file://media/materials/scripts/gazebo.material</uri>
						<name>Gazebo/White</name>
					</script>
				</material>
			</visual>
		</link>
		<link name="piston6_cylinder_link">
			<pose>0.07208130440681952 -0.04249996183700911 0.1365 0 0.30559477021812076 -2.1997995673474744</pose>
			<gravity>0</gravity>
			<visual name="piston6_cylinder_link_visual">
				<geometry>
					<cylinder>
						<radius>0.009</radius>
						<length>0.2170566290060194</length>
					</cylinder>
				</geometry>
				<material>
					<script>
						<uri>file://media/materials/scripts/gazebo.material</uri>
						<name>Gazebo/Blue</name>
					</script>
				</material>
			</visual>
		</link>
		<link name="piston1_shaft_linkU">
			<pose>0.07208130440681954 0.042499961837009104 0.1365 0 0.30559477021812076 2.199799567347474</pose>
			<gravity>0</gravity>
			<visual name="piston1_shaft_linkU_visual">
				<geometry>
					<cylinder>
						<radius>0.0045</radius>
						<length>0.2170566290060194</length>
					</cylinder>
				</geometry>
				<material>
					<script>
						<uri>file://media/materials/scripts/gazebo.material</uri>
						<name>Gazebo/Black</name>
					</script>
				</material>
			</visual>
		</link>
		<link name="piston2_shaft_linkU">
			<pose>0.0007653944073092826 0.08367422167272948 0.1365 0 0.305594770218121 -0.10540446495427853</pose>
			<gravity>0</gravity>
			<visual name="piston2_shaft_linkU_visual">
				<geometry>
					<cylinder>
						<radius>0.0045</radius>
						<length>0.2170566290060194</length>
					</cylinder>
				</geometry>
				<material>
					<script>
						<uri>file://media/materials/scripts/gazebo.material</uri>
						<name>Gazebo/Black</name>
					</script>
				</material>
			</visual>
		</link>
		<link name="piston3_shaft_linkU">
			<pose>-0.07284669881412881 0.041174259835720366 0.1365 0 0.30559477021812076 -1.9889906374389168</pose>
			<gravity>0</gravity>
			<visual name="piston3_shaft_linkU_visual">
				<geometry>
					<cylinder>
						<radius>0.0045</radius>
						<length>0.2170566290060194</length>
					</cylinder>
				</geometry>
				<material>
					<script>
						<uri>file://media/materials/scripts/gazebo.material</uri>
						<name>Gazebo/Black</name>
					</script>
				</material>
			</visual>
		</link>
		<link name="piston4_shaft_linkU">
			<pose>-0.07284669881412881 -0.04117425983572037 0.1365 0 0.30559477021812076 1.9889906374389168</pose>
			<gravity>0</gravity>
			<visual name="piston4_shaft_linkU_visual">
				<geometry>
					<cylinder>
						<radius>0.0045</radius>
						<length>0.2170566290060194</length>
					</cylinder>
				</geometry>
				<material>
					<script>
						<uri>file://media/materials/scripts/gazebo.material</uri>
						<name>Gazebo/Black</name>
					</script>
				</material>
			</visual>
		</link>
		<link name="piston5_shaft_linkU">
			<pose>0.0007653944073092965 -0.08367422167272948 0.1365 0 0.305594770218121 0.10540446495427876</pose>
			<gravity>0</gravity>
			<visual name="piston5_shaft_linkU_visual">
				<geometry>
					<cylinder>
						<radius>0.0045</radius>
						<length>0.2170566290060194</length>
					</cylinder>
				</geometry>
				<material>
					<script>
						<uri>file://media/materials/scripts/gazebo.material</uri>
						<name>Gazebo/Black</name>
					</script>
				</material>
			</visual>
		</link>
		<link name="piston6_shaft_linkU">
			<pose>0.07208130440681952 -0.04249996183700911 0.1365 0 0.30559477021812076 -2.1997995673474744</pose>
			<gravity>0</gravity>
			<visual name="piston6_shaft_linkU_visual">
				<geometry>
					<cylinder>
						<radius>0.0045</radius>
						<length>0.2170566290060194</length>
					</cylinder>
				</geometry>
				<material>
					<script>
						<uri>file://media/materials/scripts/gazebo.material</uri>
						<name>Gazebo/Black</name>
					</script>
				</material>
			</visual>
		</link>
		<link name="piston1_shaft_linkL">
			<pose>0.07208130440681954 0.042499961837009104 0.1365 0 0.30559477021812076 2.199799567347474</pose>
			<gravity>0</gravity>
			<visual name="piston1_shaft_linkL_visual">
				<geometry>
					<cylinder>
						<radius>0.0045</radius>
						<length>0.2170566290060194</length>
					</cylinder>
				</geometry>
				<material>
					<script>
						<uri>file://media/materials/scripts/gazebo.material</uri>
						<name>Gazebo/Black</name>
					</script>
				</material>
			</visual>
		</link>
		<link name="piston2_shaft_linkL">
			<pose>0.0007653944073092826 0.08367422167272948 0.1365 0 0.305594770218121 -0.10540446495427853</pose>
			<gravity>0</gravity>
			<visual name="piston2_shaft_linkL_visual">
				<geometry>
					<cylinder>
						<radius>0.0045</radius>
						<length>0.2170566290060194</length>
					</cylinder>
				</geometry>
				<material>
					<script>
						<uri>file://media/materials/scripts/gazebo.material</uri>
						<name>Gazebo/Black</name>
					</script>
				</material>
			</visual>
		</link>
		<link name="piston3_shaft_linkL">
			<pose>-0.07284669881412881 0.041174259835720366 0.1365 0 0.30559477021812076 -1.9889906374389168</pose>
			<gravity>0</gravity>
			<visual name="piston3_shaft_linkL_visual">
				<geometry>
					<cylinder>
						<radius>0.0045</radius>
						<length>0.2170566290060194</length>
					</cylinder>
				</geometry>
				<material>
					<script>
						<uri>file://media/materials/scripts/gazebo.material</uri>
						<name>Gazebo/Black</name>
					</script>
				</material>
			</visual>
		</link>
		<link name="piston4_shaft_linkL">
			<pose>-0.07284669881412881 -0.04117425983572037 0.1365 0 0.30559477021812076 1.9889906374389168</pose>
			<gravity>0</gravity>
			<visual name="piston4_shaft_linkL_visual">
				<geometry>
					<cylinder>
						<radius>0.0045</radius>
						<length>0.2170566290060194</length>
					</cylinder>
				</geometry>
				<material>
					<script>
						<uri>file://media/materials/scripts/gazebo.material</uri>
						<name>Gazebo/Black</name>
					</script>
				</material>
			</visual>
		</link>
		<link name="piston5_shaft_linkL">
			<pose>0.0007653944073092965 -0.08367422167272948 0.1365 0 0.305594770218121 0.10540446495427876</pose>
			<gravity>0</gravity>
			<visual name="piston5_shaft_linkL_visual">
				<geometry>
					<cylinder>
						<radius>0.0045</radius>
						<length>0.2170566290060194</length>
					</cylinder>
				</geometry>
				<material>
					<script>
						<uri>file://media/materials/scripts/gazebo.material</uri>
						<name>Gazebo/Black</name>
					</script>
				</material>
			</visual>
		</link>
		<link name="piston6_shaft_linkL">
			<pose>0.07208130440681952 -0.04249996183700911 0.1365 0 0.30559477021812076 -2.1997995673474744</pose>
			<gravity>0</gravity>
			<visual name="piston6_shaft_linkL_visual">
				<geometry>
					<cylinder>
						<radius>0.0045</radius>
						<length>0.2170566290060194</length>
					</cylinder>
				</geometry>
				<material>
					<script>
						<uri>file://media/materials/scripts/gazebo.material</uri>
						<name>Gazebo/Black</name>
					</script>
				</material>
			</visual>
		</link>
		<plugin filename="libgz-sim-detachable-joint-system.so" name="gz::sim::systems::DetachableJoint">
			<parent_link>piston1_shaft_linkL</parent_link>
			<child_link>piston1_shaft_linkU</child_link>
			<child_model>stewart</child_model>
		</plugin>
		<plugin filename="libgz-sim-detachable-joint-system.so" name="gz::sim::systems::DetachableJoint">
			<parent_link>piston2_shaft_linkL</parent_link>
			<child_link>piston2_shaft_linkU</child_link>
			<child_model>stewart</child_model>
		</plugin>
		<plugin filename="libgz-sim-detachable-joint-system.so" name="gz::sim::systems::DetachableJoint">
			<parent_link>piston3_shaft_linkL</parent_link>
			<child_link>piston3_shaft_linkU</child_link>
			<child_model>stewart</child_model>
		</plugin>
		<plugin filename="libgz-sim-detachable-joint-system.so" name="gz::sim::systems::DetachableJoint">
			<parent_link>piston4_shaft_linkL</parent_link>
			<child_link>piston4_shaft_linkU</child_link>
			<child_model>stewart</child_model>
		</plugin>
		<plugin filename="libgz-sim-detachable-joint-system.so" name="gz::sim::systems::DetachableJoint">
			<parent_link>piston5_shaft_linkL</parent_link>
			<child_link>piston5_shaft_linkU</child_link>
			<child_model>stewart</child_model>
		</plugin>
		<plugin filename="libgz-sim-detachable-joint-system.so" name="gz::sim::systems::DetachableJoint">
			<parent_link>piston6_shaft_linkL</parent_link>
			<child_link>piston6_shaft_linkU</child_link>
			<child_model>stewart</child_model>
		</plugin>
		<plugin filename="gz-sim-joint-position-controller-system" name="gz::sim::systems::JointPositionController">
			<joint_name>piston1_prismatic_joint</joint_name>
			<p_gain>50000</p_gain>
			<i_gain>10000</i_gain>
			<d_gain>1000</d_gain>
		</plugin>
		<plugin filename="gz-sim-joint-position-controller-system" name="gz::sim::systems::JointPositionController">
			<joint_name>piston2_prismatic_joint</joint_name>
			<p_gain>50000</p_gain>
			<i_gain>10000</i_gain>
			<d_gain>1000</d_gain>
		</plugin>
		<plugin filename="gz-sim-joint-position-controller-system" name="gz::sim::systems::JointPositionController">
			<joint_name>piston3_prismatic_joint</joint_name>
			<p_gain>50000</p_gain>
			<i_gain>10000</i_gain>
			<d_gain>1000</d_gain>
		</plugin>
		<plugin filename="gz-sim-joint-position-controller-system" name="gz::sim::systems::JointPositionController">
			<joint_name>piston4_prismatic_joint</joint_name>
			<p_gain>50000</p_gain>
			<i_gain>10000</i_gain>
			<d_gain>1000</d_gain>
		</plugin>
		<plugin filename="gz-sim-joint-position-controller-system" name="gz::sim::systems::JointPositionController">
			<joint_name>piston5_prismatic_joint</joint_name>
			<p_gain>50000</p_gain>
			<i_gain>10000</i_gain>
			<d_gain>1000</d_gain>
		</plugin>
		<plugin filename="gz-sim-joint-position-controller-system" name="gz::sim::systems::JointPositionController">
			<joint_name>piston6_prismatic_joint</joint_name>
			<p_gain>50000</p_gain>
			<i_gain>10000</i_gain>
			<d_gain>1000</d_gain>
		</plugin>
	</model>
</sdf>
